Workbook

Sheet Stato patrimoniale
A1: ID | B1: Statistiche | C1: Nome | D1: Tipo | E1: Classe | F1: Area | G1: Settore | H1: Emittente | I1: Quantità | J1: Valuta | K1: ISIN | L1: Ticker | M1: Ticker Data | N1: Tassa | O1: Data_Acquisto | P1: Mercato | Q1: Intermediario | R1: Prezzo_Acquisto | S1: Commissioni | T1: Spese valuta | U1: Cambio | V1: Spese euro acquisto | W1: Costo | X1: Mercato | Y1: Intermediario | Z1: Prezzo | AA1: Variazione quantità | AB1: Cambio | AC1: Dividendi totali euro | AD1: Valore | AE1: Delta | AF1: Delta percentuale | AG1: Data_Vendita | AH1: Mercato | AI1: Intermediario | AJ1: Prezzo_Vendita | AK1: Commissioni | AL1: Spese valuta | AM1: Cambio | AN1: Spese euro vendita | AO1: Cedole nette | AP1: Ricavo | AQ1: Guadagno | AR1: Guadagno percentuale | AS1: Tassa plusvalenza | AT1: Guadagno netto
A2: 13 | B2: 1 | C2: CNH Industrial | D2: A | E2: Azioni | F2: Italia | G2: Auto | H2: Italia | I2: 18 | J2: EUR | K2: NL0010545661 | L2: CNHI.VI | M2: #VALUE! | N2: 0.26 | O2: 45133 | P2: Milano | Q2: Fineco-C | R2: 13.863 | S2: 0 | T2: 0 | U2: 1 | W2: =(I2/IF(OR(D2="O",D2="CE"),100,1)*R2*(1+S2)+T2)*U2+V2 -> 249.534 | X2: Milano | Y2: Fineco-C | Z2: 9.13 | AA2: =SUMIF(Operazioni!A:A,A2,Operazioni!C:C) -> 0 | AB2: =INDEX(Valute!B:B,MATCH(J2,Valute!A:A,0)) -> 1 | AC2: =SUMIF(Operazioni!A:A,A2,Operazioni!K:K) -> 5.8016 | AD2: =((I2+AA2)/IF(OR(D2="O",D2="CE"),100,1)*Z2)*AB2+AC2 -> 170.1416 | AE2: =AD2-W2 -> -79.3924 | AF2: =IF(W2<>0,AE2/W2,"") -> -0.31816265 | AG2: 45531 | AH2: Milano | AI2: Fineco-C | AJ2: 9.13 | AL2: 2.95 | AM2: 1 | AO2: =AC2*(1-N2) -> 4.293184 | AP2: =((I2+AA2)/IF(OR(D2="O",D2="CE"),100,1)*AJ2*(1-AK2)-AL2)*AM2-AN2+AC2 -> 167.1916 | AQ2: =AP2-W2 -> -82.3424 | AR2: =IF(W2<>0,AQ2/W2,"") -> -0.32998469 | AS2: =(AQ2-AC2)*N2 -> -22.91744 | AT2: =IF(W2<>0,(AQ2-AS2)/W2,"") -> -0.23814374
A3: 14 | B3: 1 | C3: Unicredit | D3: A | E3: Azioni | F3: Italia | G3: Banca | H3: Italia | I3: 11 | J3: EUR | K3: IT0005239360 | L3: UCG.MI | M3: #VALUE! | N3: 0.26 | O3: 45132 | P3: Milano | Q3: Fineco-C | R3: 22.418 | S3: 0 | T3: 0 | U3: 1 | W3: =(I3/IF(OR(D3="O",D3="CE"),100,1)*R3*(1+S3)+T3)*U3+V3 -> 246.598 | X3: Milano | Y3: Fineco-C | Z3: 45 | AA3: =SUMIF(Operazioni!A:A,A3,Operazioni!C:C) -> 0 | AB3: =INDEX(Valute!B:B,MATCH(J3,Valute!A:A,0)) -> 1 | AC3: =SUMIF(Operazioni!A:A,A3,Operazioni!K:K) -> 22.2148 | AD3: =((I3+AA3)/IF(OR(D3="O",D3="CE"),100,1)*Z3)*AB3+AC3 -> 517.2148 | AE3: =AD3-W3 -> 270.6168 | AF3: =IF(W3<>0,AE3/W3,"") -> 1.0974006 | AG3: 45691 | AH3: Milano | AI3: Fineco-C | AJ3: 45 | AL3: 2.95 | AM3: 1 | AO3: =AC3*(1-N3) -> 16.438952 | AP3: =((I3+AA3)/IF(OR(D3="O",D3="CE"),100,1)*AJ3*(1-AK3)-AL3)*AM3-AN3+AC3 -> 514.2648 | AQ3: =AP3-W3 -> 267.6668 | AR3: =IF(W3<>0,AQ3/W3,"") -> 1.0854378 | AS3: =(AQ3-AC3)*N3 -> 63.81752 | AT3: =IF(W3<>0,(AQ3-AS3)/W3,"") -> 0.82664612
A4: 15 | B4: 1 | C4: Poste Italiane | D4: A | E4: Azioni | F4: Italia | G4: Distribuzione | H4: Italia | I4: 25 | J4: EUR | K4: IT0003796171 | L4: PST.MI | M4: #VALUE! | N4: 0.26 | O4: 45133 | P4: Milano | Q4: Fineco-C | R4: 10.278 | S4: 0 | T4: 0 | U4: 1 | W4: =(I4/IF(OR(D4="O",D4="CE"),100,1)*R4*(1+S4)+T4)*U4+V4 -> 256.95 | X4: Milano | Y4: Fineco-C | Z4: {=_FV(M4,"Price",TRUE)} -> 25.39 | AA4: =SUMIF(Operazioni!A:A,A4,Operazioni!C:C) -> 0 | AB4: =INDEX(Valute!B:B,MATCH(J4,Valute!A:A,0)) -> 1 | AC4: =SUMIF(Operazioni!A:A,A4,Operazioni!K:K) -> 34.7874 | AD4: =((I4+AA4)/IF(OR(D4="O",D4="CE"),100,1)*Z4)*AB4+AC4 -> 669.5374 | AE4: =AD4-W4 -> 412.5874 | AF4: =IF(W4<>0,AE4/W4,"") -> 1.6057108 | AG4: 45992 | AH4: Milano | AI4: Fineco-C | AJ4: 20.56 | AL4: 2.95 | AM4: 1 | AO4: =AC4*(1-N4) -> 25.742676 | AP4: =((I4+AA4)/IF(OR(D4="O",D4="CE"),100,1)*AJ4*(1-AK4)-AL4)*AM4-AN4+AC4 -> 545.8374 | AQ4: =AP4-W4 -> 288.8874 | AR4: =IF(W4<>0,AQ4/W4,"") -> 1.1242942 | AS4: =(AQ4-AC4)*N4 -> 66.066 | AT4: =IF(W4<>0,(AQ4-AS4)/W4,"") -> 0.86717805
A5: 16 | B5: 1 | C5: STMicroElectronics | D5: A | E5: Azioni | F5: Italia | G5: Tecnologia | H5: Italia | I5: 5 | J5: EUR | K5: NL0000226223 | L5: STMMI.MI | M5: #VALUE! | N5: 0.26 | O5: 45132 | P5: Milano | Q5: Fineco-C | R5: 46.09 | S5: 0 | T5: 0 | U5: 1 | W5: =(I5/IF(OR(D5="O",D5="CE"),100,1)*R5*(1+S5)+T5)*U5+V5 -> 230.45 | X5: Milano | Y5: Fineco-C | Z5: 27.8 | AA5: =SUMIF(Operazioni!A:A,A5,Operazioni!C:C) -> 0 | AB5: =INDEX(Valute!B:B,MATCH(J5,Valute!A:A,0)) -> 1 | AC5: =SUMIF(Operazioni!A:A,A5,Operazioni!K:K) -> 0.7992 | AD5: =((I5+AA5)/IF(OR(D5="O",D5="CE"),100,1)*Z5)*AB5+AC5 -> 139.7992 | AE5: =AD5-W5 -> -90.6508 | AF5: =IF(W5<>0,AE5/W5,"") -> -0.39336429 | AG5: 45531 | AH5: Milano | AI5: Fineco-C | AJ5: 27.8 | AL5: 2.95 | AM5: 1 | AO5: =AC5*(1-N5) -> 0.591408 | AP5: =((I5+AA5)/IF(OR(D5="O",D5="CE"),100,1)*AJ5*(1-AK5)-AL5)*AM5-AN5+AC5 -> 136.8492 | AQ5: =AP5-W5 -> -93.6008 | AR5: =IF(W5<>0,AQ5/W5,"") -> -0.40616533 | AS5: =(AQ5-AC5)*N5 -> -24.544 | AT5: =IF(W5<>0,(AQ5-AS5)/W5,"") -> -0.29966066
A6: 17 | B6: 1 | C6: Intesa San Paolo | D6: A | E6: Azioni | F6: Italia | G6: Banca | H6: Italia | I6: 100 | J6: EUR | K6: IT0000072618 | L6: ISP.MI | M6: #VALUE! | N6: 0.26 | O6: 45132 | P6: Milano | Q6: Fineco-C | R6: 2.5545 | S6: 0 | T6: 0 | U6: 1 | W6: =(I6/IF(OR(D6="O",D6="CE"),100,1)*R6*(1+S6)+T6)*U6+V6 -> 255.45 | X6: Milano | Y6: Fineco-C | Z6: 5.109 | AA6: =SUMIF(Operazioni!A:A,A6,Operazioni!C:C) -> 0 | AB6: =INDEX(Valute!B:B,MATCH(J6,Valute!A:A,0)) -> 1 | AC6: =SUMIF(Operazioni!A:A,A6,Operazioni!K:K) -> 47.138 | AD6: =((I6+AA6)/IF(OR(D6="O",D6="CE"),100,1)*Z6)*AB6+AC6 -> 558.038 | AE6: =AD6-W6 -> 302.588 | AF6: =IF(W6<>0,AE6/W6,"") -> 1.1845293 | AG6: 45862 | AH6: Milano | AI6: Fineco-C | AJ6: 5.109 | AL6: 2.95 | AM6: 1 | AO6: =AC6*(1-N6) -> 34.88212 | AP6: =((I6+AA6)/IF(OR(D6="O",D6="CE"),100,1)*AJ6*(1-AK6)-AL6)*AM6-AN6+AC6 -> 555.088 | AQ6: =AP6-W6 -> 299.638 | AR6: =IF(W6<>0,AQ6/W6,"") -> 1.172981 | AS6: =(AQ6-AC6)*N6 -> 65.65 | AT6: =IF(W6<>0,(AQ6-AS6)/W6,"") -> 0.91598356
A7: 18 | B7: 1 | C7: Leonardo | D7: A | E7: Azioni | F7: Italia | G7: Industria | H7: Italia | I7: 21 | J7: EUR | K7: IT0003856405 | L7: LDO.MI | M7: #VALUE! | N7: 0.26 | O7: 45133 | P7: Milano | Q7: Fineco-C | R7: 11.64 | S7: 0 | T7: 0 | U7: 1 | W7: =(I7/IF(OR(D7="O",D7="CE"),100,1)*R7*(1+S7)+T7)*U7+V7 -> 244.44 | X7: Milano | Y7: Fineco-C | Z7: 23.95 | AA7: =SUMIF(Operazioni!A:A,A7,Operazioni!C:C) -> 0 | AB7: =INDEX(Valute!B:B,MATCH(J7,Valute!A:A,0)) -> 1 | AC7: =SUMIF(Operazioni!A:A,A7,Operazioni!K:K) -> 0 | AD7: =((I7+AA7)/IF(OR(D7="O",D7="CE"),100,1)*Z7)*AB7+AC7 -> 502.95 | AE7: =AD7-W7 -> 258.51 | AF7: =IF(W7<>0,AE7/W7,"") -> 1.0575601 | AG7: 45446 | AH7: Milano | AI7: Fineco-C | AJ7: 23.95 | AL7: 2.95 | AM7: 1 | AO7: =AC7*(1-N7) -> 0 | AP7: =((I7+AA7)/IF(OR(D7="O",D7="CE"),100,1)*AJ7*(1-AK7)-AL7)*AM7-AN7+AC7 -> 500 | AQ7: =AP7-W7 -> 255.56 | AR7: =IF(W7<>0,AQ7/W7,"") -> 1.0454917 | AS7: =(AQ7-AC7)*N7 -> 66.4456 | AT7: =IF(W7<>0,(AQ7-AS7)/W7,"") -> 0.77366388
A8: 19 | B8: 1 | C8: Enel | D8: A | E8: Azioni | F8: Italia | G8: Energia | H8: Italia | I8: 40 | J8: EUR | K8: IT0003128367 | L8: ENEL.MI | M8: #VALUE! | N8: 0.26 | O8: 45133 | P8: Milano | Q8: Fineco-C | R8: 6.313 | S8: 0 | T8: 0 | U8: 1 | W8: =(I8/IF(OR(D8="O",D8="CE"),100,1)*R8*(1+S8)+T8)*U8+V8 -> 252.52 | X8: Milano | Y8: Fineco-C | Z8: {=_FV(M8,"Price",TRUE)} -> 9.862 | AA8: =SUMIF(Operazioni!A:A,A8,Operazioni!C:C) -> 0 | AB8: =INDEX(Valute!B:B,MATCH(J8,Valute!A:A,0)) -> 1 | AC8: =SUMIF(Operazioni!A:A,A8,Operazioni!K:K) -> 34.632 | AD8: =((I8+AA8)/IF(OR(D8="O",D8="CE"),100,1)*Z8)*AB8+AC8 -> 429.112 | AE8: =AD8-W8 -> 176.592 | AF8: =IF(W8<>0,AE8/W8,"") -> 0.69931887 | AO8: =AC8*(1-N8) -> 25.62768 | AP8: =((I8+AA8)/IF(OR(D8="O",D8="CE"),100,1)*AJ8*(1-AK8)-AL8)*AM8-AN8+AC8 -> 34.632 | AQ8: =AP8-W8 -> -217.888 | AR8: =IF(W8<>0,AQ8/W8,"") -> -0.86285443 | AS8: =(AQ8-AC8)*N8 -> -65.6552 | AT8: =IF(W8<>0,(AQ8-AS8)/W8,"") -> -0.60285443
A9: 20 | B9: 1 | C9: Eni | D9: A | E9: Azioni | F9: Italia | G9: Energia | H9: Italia | I9: 19 | J9: EUR | K9: IT0003132476 | L9: ENI.MI | M9: #VALUE! | N9: 0.26 | O9: 45132 | P9: Milano | Q9: Fineco-C | R9: 13.947 | S9: 0 | T9: 0 | U9: 1 | W9: =(I9/IF(OR(D9="O",D9="CE"),100,1)*R9*(1+S9)+T9)*U9+V9 -> 264.993 | X9: Milano | Y9: Fineco-C | Z9: {=_FV(M9,"Price",TRUE)} -> 23.185 | AA9: =SUMIF(Operazioni!A:A,A9,Operazioni!C:C) -> 0 | AB9: =INDEX(Valute!B:B,MATCH(J9,Valute!A:A,0)) -> 1 | AC9: =SUMIF(Operazioni!A:A,A9,Operazioni!K:K) -> 39.035 | AD9: =((I9+AA9)/IF(OR(D9="O",D9="CE"),100,1)*Z9)*AB9+AC9 -> 479.55 | AE9: =AD9-W9 -> 214.557 | AF9: =IF(W9<>0,AE9/W9,"") -> 0.80967045 | AO9: =AC9*(1-N9) -> 28.8859 | AP9: =((I9+AA9)/IF(OR(D9="O",D9="CE"),100,1)*AJ9*(1-AK9)-AL9)*AM9-AN9+AC9 -> 39.035 | AQ9: =AP9-W9 -> -225.958 | AR9: =IF(W9<>0,AQ9/W9,"") -> -0.85269422 | AS9: =(AQ9-AC9)*N9 -> -68.89818 | AT9: =IF(W9<>0,(AQ9-AS9)/W9,"") -> -0.59269422
A10: 21 | B10: 1 | C10: Apple | D10: A | E10: Azioni | F10: US | G10: Tecnologia | H10: US | I10: 2 | J10: USD | K10: US0378331005 | L10: AAPL | M10: #VALUE! | N10: 0.26 | O10: 44498 | P10: Nasdaq | Q10: Fineco-C | R10: 155.27 | S10: 0.003 | T10: 0 | U10: 0.864 | V10: 12.95 | W10: =(I10/IF(OR(D10="O",D10="CE"),100,1)*R10*(1+S10)+T10)*U10+V10 -> 282.06148 | X10: Nasdaq | Y10: Fineco-C | Z10: {=_FV(M10,"Price",TRUE)} -> 308.82 | AA10: =SUMIF(Operazioni!A:A,A10,Operazioni!C:C) -> 0 | AB10: =INDEX(Valute!B:B,MATCH(J10,Valute!A:A,0)) -> 0.86002565 | AC10: =SUMIF(Operazioni!A:A,A10,Operazioni!K:K) -> 5.6018 | AD10: =((I10+AA10)/IF(OR(D10="O",D10="CE"),100,1)*Z10)*AB10+AC10 -> 536.78804 | AE10: =AD10-W10 -> 254.72656 | AF10: =IF(W10<>0,AE10/W10,"") -> 0.9030888 | AO10: =AC10*(1-N10) -> 4.145332 | AP10: =((I10+AA10)/IF(OR(D10="O",D10="CE"),100,1)*AJ10*(1-AK10)-AL10)*AM10-AN10+AC10 -> 5.6018 | AQ10: =AP10-W10 -> -276.45968 | AR10: =IF(W10<>0,AQ10/W10,"") -> -0.98013979 | AS10: =(AQ10-AC10)*N10 -> -73.335985 | AT10: =IF(W10<>0,(AQ10-AS10)/W10,"") -> -0.72013979
A11: 22 | B11: 1 | C11: Amazon | D11: A | E11: Azioni | F11: US | G11: Tecnologia | H11: US | I11: 2 | J11: USD | K11: US0231351067 | L11: AMZN | M11: #VALUE! | N11: 0.26 | O11: 45044 | P11: Nasdaq | Q11: Fineco-C | R11: 112.3447 | S11: 0.003 | T11: 0 | U11: 0.9089 | V11: 12.95 | W11: =(I11/IF(OR(D11="O",D11="CE"),100,1)*R11*(1+S11)+T11)*U11+V11 -> 217.78286 | X11: Nasdaq | Y11: Fineco-C | Z11: {=_FV(M11,"Price",TRUE)} -> 266.32 | AA11: =SUMIF(Operazioni!A:A,A11,Operazioni!C:C) -> 0 | AB11: =INDEX(Valute!B:B,MATCH(J11,Valute!A:A,0)) -> 0.86002565 | AC11: =SUMIF(Operazioni!A:A,A11,Operazioni!K:K) -> 0 | AD11: =((I11+AA11)/IF(OR(D11="O",D11="CE"),100,1)*Z11)*AB11+AC11 -> 458.08406 | AE11: =AD11-W11 -> 240.30121 | AF11: =IF(W11<>0,AE11/W11,"") -> 1.1033982 | AG11: 45992 | AH11: Nasdaq | AI11: Fineco | AJ11: 228.5254 | AL11: 10 | AM11: 0.8572 | AO11: =AC11*(1-N11) -> 0 | AP11: =((I11+AA11)/IF(OR(D11="O",D11="CE"),100,1)*AJ11*(1-AK11)-AL11)*AM11-AN11+AC11 -> 383.21195 | AQ11: =AP11-W11 -> 165.42909 | AR11: =IF(W11<>0,AQ11/W11,"") -> 0.75960566 | AS11: =(AQ11-AC11)*N11 -> 43.011563 | AT11: =IF(W11<>0,(AQ11-AS11)/W11,"") -> 0.56210819
A12: 32 | B12: 1 | C12: Microsoft | D12: A | E12: Azioni | F12: US | G12: Tecnologia | H12: US | I12: 10 | J12: USD | K12: US5949181045 | L12: MSFT | M12: #VALUE! | N12: 0.26 | O12: 42006 | P12: Nasdaq | Q12: Fineco-C | R12: 173.18 | S12: 0 | T12: 0 | U12: 1 | W12: =(I12/IF(OR(D12="O",D12="CE"),100,1)*R12*(1+S12)+T12)*U12+V12 -> 1731.8 | X12: Nasdaq | Y12: Fineco-C | Z12: 378.7 | AA12: =SUMIF(Operazioni!A:A,A12,Operazioni!C:C) -> 0 | AB12: =INDEX(Valute!B:B,MATCH(J12,Valute!A:A,0)) -> 0.86002565 | AC12: =SUMIF(Operazioni!A:A,A12,Operazioni!K:K) -> 0 | AD12: =((I12+AA12)/IF(OR(D12="O",D12="CE"),100,1)*Z12)*AB12+AC12 -> 3256.9171 | AE12: =AD12-W12 -> 1525.1171 | AF12: =IF(W12<>0,AE12/W12,"") -> 0.88065431 | AG12: 45301 | AH12: Nasdaq | AI12: Fineco-C | AJ12: 378.7 | AL12: 23.53 | AM12: 0.9116 | AO12: =AC12*(1-N12) -> 0 | AP12: =((I12+AA12)/IF(OR(D12="O",D12="CE"),100,1)*AJ12*(1-AK12)-AL12)*AM12-AN12+AC12 -> 3430.7793 | AQ12: =AP12-W12 -> 1698.9793 | AR12: =IF(W12<>0,AQ12/W12,"") -> 0.98104819 | AS12: =(AQ12-AC12)*N12 -> 441.73461 | AT12: =IF(W12<>0,(AQ12-AS12)/W12,"") -> 0.72597566
A13: 30 | B13: 1 | C13: Microsoft | D13: A | E13: Azioni | F13: US | G13: Tecnologia | H13: US | I13: 17 | J13: USD | K13: US5949181045 | L13: MSFT | M13: #VALUE! | N13: 0.26 | O13: 45279 | P13: Nasdaq | Q13: Fineco-C | R13: 173.18 | S13: 0 | T13: 0 | U13: 1 | W13: =(I13/IF(OR(D13="O",D13="CE"),100,1)*R13*(1+S13)+T13)*U13+V13 -> 2944.06 | X13: Nasdaq | Y13: Fineco-C | Z13: {=_FV(M13,"Price",TRUE)} -> 418.57 | AA13: =SUMIF(Operazioni!A:A,A13,Operazioni!C:C) -> 0 | AB13: =INDEX(Valute!B:B,MATCH(J13,Valute!A:A,0)) -> 0.86002565 | AC13: =SUMIF(Operazioni!A:A,A13,Operazioni!K:K) -> 0 | AD13: =((I13+AA13)/IF(OR(D13="O",D13="CE"),100,1)*Z13)*AB13+AC13 -> 6119.6759 | AE13: =AD13-W13 -> 3175.6159 | AF13: =IF(W13<>0,AE13/W13,"") -> 1.0786519 | AO13: =AC13*(1-N13) -> 0 | AP13: =((I13+AA13)/IF(OR(D13="O",D13="CE"),100,1)*AJ13*(1-AK13)-AL13)*AM13-AN13+AC13 -> 0 | AQ13: =AP13-W13 -> -2944.06 | AR13: =IF(W13<>0,AQ13/W13,"") -> -1 | AS13: =(AQ13-AC13)*N13 -> -765.4556 | AT13: =IF(W13<>0,(AQ13-AS13)/W13,"") -> -0.74
A14: 54 | B14: 1 | C14: Microsoft | D14: A | E14: Azioni | F14: US | G14: Tecnologia | H14: US | I14: 10 | J14: USD | K14: US5949181045 | L14: MSFT | M14: #VALUE! | N14: 0.26 | O14: 42006 | P14: Nasdaq | Q14: Fineco-C | R14: 173.18 | S14: 0 | T14: 0 | U14: 1 | W14: =(I14/IF(OR(D14="O",D14="CE"),100,1)*R14*(1+S14)+T14)*U14+V14 -> 1731.8 | X14: Nasdaq | Y14: Fineco-C | Z14: 454.6 | AA14: =SUMIF(Operazioni!A:A,A14,Operazioni!C:C) -> 0 | AB14: =INDEX(Valute!B:B,MATCH(J14,Valute!A:A,0)) -> 0.86002565 | AC14: =SUMIF(Operazioni!A:A,A14,Operazioni!K:K) -> 0 | AD14: =((I14+AA14)/IF(OR(D14="O",D14="CE"),100,1)*Z14)*AB14+AC14 -> 3909.6766 | AE14: =AD14-W14 -> 2177.8766 | AF14: =IF(W14<>0,AE14/W14,"") -> 1.2575797 | AG14: 45638 | AH14: Nasdaq | AI14: Fineco-C | AJ14: 454.6 | AL14: 27.28 | AM14: 0.9553 | AO14: =AC14*(1-N14) -> 0 | AP14: =((I14+AA14)/IF(OR(D14="O",D14="CE"),100,1)*AJ14*(1-AK14)-AL14)*AM14-AN14+AC14 -> 4316.7332 | AQ14: =AP14-W14 -> 2584.9332 | AR14: =IF(W14<>0,AQ14/W14,"") -> 1.492628 | AS14: =((AQ14-AC14)*N14)-240.53 -> 431.55264 | AT14: =IF(W14<>0,(AQ14-AS14)/W14,"") -> 1.2434349
A15: 23 | B15: 1 | C15: Microsoft | D15: A | E15: Azioni | F15: US | G15: Tecnologia | H15: US | I15: 49 | J15: USD | K15: US5949181045 | L15: MSFT | M15: #VALUE! | N15: 0.26 | O15: 42006 | P15: Nasdaq | Q15: Fineco-C | R15: 173.18 | S15: 0 | T15: 0 | U15: 1 | W15: =(I15/IF(OR(D15="O",D15="CE"),100,1)*R15*(1+S15)+T15)*U15+V15 -> 8485.82 | X15: Nasdaq | Y15: Fineco-C | Z15: {=_FV(M15,"Price",TRUE)} -> 418.57 | AA15: =SUMIF(Operazioni!A:A,A15,Operazioni!C:C) -> 0 | AB15: =INDEX(Valute!B:B,MATCH(J15,Valute!A:A,0)) -> 0.86002565 | AC15: =SUMIF(Operazioni!A:A,A15,Operazioni!K:K) -> 626.3878 | AD15: =((I15+AA15)/IF(OR(D15="O",D15="CE"),100,1)*Z15)*AB15+AC15 -> 18265.454 | AE15: =AD15-W15 -> 9779.6337 | AF15: =IF(W15<>0,AE15/W15,"") -> 1.1524677 | AO15: =AC15*(1-N15) -> 463.52697 | AP15: =((I15+AA15)/IF(OR(D15="O",D15="CE"),100,1)*AJ15*(1-AK15)-AL15)*AM15-AN15+AC15 -> 626.3878 | AQ15: =AP15-W15 -> -7859.4322 | AR15: =IF(W15<>0,AQ15/W15,"") -> -0.92618418 | AS15: =(AQ15-AC15)*N15 -> -2206.3132 | AT15: =IF(W15<>0,(AQ15-AS15)/W15,"") -> -0.66618418
A16: 82 | B16: 1 | C16: Microsoft | D16: A | E16: Azioni | F16: US | G16: Tecnologia | H16: US | I16: 17 | J16: USD | K16: US5949181045 | L16: MSFT | M16: #VALUE! | N16: 0.26 | O16: 42359 | P16: Nasdaq | Q16: Fineco | R16: 399.122 | S16: 0 | T16: 0 | U16: 1 | W16: =(I16/IF(OR(D16="O",D16="CE"),100,1)*R16*(1+S16)+T16)*U16+V16 -> 6785.074 | X16: Nasdaq | Y16: Fineco | Z16: {=_FV(M16,"Price",TRUE)} -> 418.57 | AA16: =SUMIF(Operazioni!A:A,A16,Operazioni!C:C) -> 0 | AB16: =INDEX(Valute!B:B,MATCH(J16,Valute!A:A,0)) -> 0.86002565 | AC16: =SUMIF(Operazioni!A:A,A16,Operazioni!K:K) -> 0 | AD16: =((I16+AA16)/IF(OR(D16="O",D16="CE"),100,1)*Z16)*AB16+AC16 -> 6119.6759 | AE16: =AD16-W16 -> -665.39808 | AF16: =IF(W16<>0,AE16/W16,"") -> -0.098067918
A17: 56 | B17: 1 | C17: Microsoft | D17: A | E17: Azioni | F17: US | G17: Tecnologia | H17: US | I17: 17 | J17: USD | K17: US5949181045 | L17: MSFT | M17: #VALUE! | N17: 0.26 | O17: 45667 | P17: Nasdaq | Q17: Fineco | R17: 399.122 | S17: 0 | T17: 0 | U17: 1 | W17: =(I17/IF(OR(D17="O",D17="CE"),100,1)*R17*(1+S17)+T17)*U17+V17 -> 6785.074 | X17: Nasdaq | Y17: Fineco | Z17: {=_FV(M17,"Price",TRUE)} -> 418.57 | AA17: =SUMIF(Operazioni!A:A,A17,Operazioni!C:C) -> 0 | AB17: =INDEX(Valute!B:B,MATCH(J17,Valute!A:A,0)) -> 0.86002565 | AC17: =SUMIF(Operazioni!A:A,A17,Operazioni!K:K) -> 0 | AD17: =((I17+AA17)/IF(OR(D17="O",D17="CE"),100,1)*Z17)*AB17+AC17 -> 6119.6759 | AE17: =AD17-W17 -> -665.39808 | AF17: =IF(W17<>0,AE17/W17,"") -> -0.098067918
A18: 1 | B18: 1 | C18: iShares Core MSCI World UCITS ETF USD (Acc) | D18: ETF | E18: Azioni | F18: Mondo Sviluppato | H18: iShares | I18: 10 | J18: EUR | K18: IE00B4L5Y983 | L18: SWDA.MI | M18: #VALUE! | N18: 0.26 | O18: 45096 | P18: Milano | Q18: Fineco-C | R18: 76.88 | S18: 0 | T18: 0 | U18: 1 | W18: =(I18/IF(OR(D18="O",D18="CE"),100,1)*R18*(1+S18)+T18)*U18+V18 -> 768.8 | X18: Milano | Y18: Fineco-C | Z18: {=_FV(M18,"Price",TRUE)} -> 123.26 | AA18: =SUMIF(Operazioni!A:A,A18,Operazioni!C:C) -> 0 | AB18: =INDEX(Valute!B:B,MATCH(J18,Valute!A:A,0)) -> 1 | AC18: =SUMIF(Operazioni!A:A,A18,Operazioni!K:K) -> 0 | AD18: =((I18+AA18)/IF(OR(D18="O",D18="CE"),100,1)*Z18)*AB18+AC18 -> 1232.6 | AE18: =AD18-W18 -> 463.8 | AF18: =IF(W18<>0,AE18/W18,"") -> 0.60327784 | AO18: =AC18*(1-N18) -> 0 | AP18: =((I18+AA18)/IF(OR(D18="O",D18="CE"),100,1)*AJ18*(1-AK18)-AL18)*AM18-AN18+AC18 -> 0 | AQ18: =AP18-W18 -> -768.8 | AR18: =IF(W18<>0,AQ18/W18,"") -> -1 | AS18: =(AQ18-AC18)*N18 -> -199.888 | AT18: =IF(W18<>0,(AQ18-AS18)/W18,"") -> -0.74
A19: 2 | B19: 1 | C19: iShares Core MSCI World UCITS ETF USD (Acc) | D19: ETF | E19: Azioni | F19: Mondo Sviluppato | H19: iShares | I19: 3 | J19: EUR | K19: IE00B4L5Y983 | L19: SWDA.MI | M19: #VALUE! | N19: 0.26 | O19: 45131 | P19: Milano | Q19: Fineco-C | R19: 77.38 | S19: 0 | T19: 0 | U19: 1 | W19: =(I19/IF(OR(D19="O",D19="CE"),100,1)*R19*(1+S19)+T19)*U19+V19 -> 232.14 | X19: Milano | Y19: Fineco-C | Z19: {=_FV(M19,"Price",TRUE)} -> 123.26 | AA19: =SUMIF(Operazioni!A:A,A19,Operazioni!C:C) -> 0 | AB19: =INDEX(Valute!B:B,MATCH(J19,Valute!A:A,0)) -> 1 | AC19: =SUMIF(Operazioni!A:A,A19,Operazioni!K:K) -> 0 | AD19: =((I19+AA19)/IF(OR(D19="O",D19="CE"),100,1)*Z19)*AB19+AC19 -> 369.78 | AE19: =AD19-W19 -> 137.64 | AF19: =IF(W19<>0,AE19/W19,"") -> 0.59291807 | AO19: =AC19*(1-N19) -> 0 | AP19: =((I19+AA19)/IF(OR(D19="O",D19="CE"),100,1)*AJ19*(1-AK19)-AL19)*AM19-AN19+AC19 -> 0 | AQ19: =AP19-W19 -> -232.14 | AR19: =IF(W19<>0,AQ19/W19,"") -> -1 | AS19: =(AQ19-AC19)*N19 -> -60.3564 | AT19: =IF(W19<>0,(AQ19-AS19)/W19,"") -> -0.74
A20: 3 | B20: 1 | C20: Vanguard FTSE Emerging Markets UCITS ETF (USD) Dis | D20: ETF | E20: Azioni | F20: Paesi Emergenti | H20: Vanguard | I20: 10 | J20: EUR | K20: IE00B3VVMM84 | L20: VFEM.MI | M20: #VALUE! | N20: 0.26 | O20: 45096 | P20: Milano | Q20: Fineco-C | R20: 51.31 | S20: 0 | T20: 0 | U20: 1 | V20: 2.95 | W20: =(I20/IF(OR(D20="O",D20="CE"),100,1)*R20*(1+S20)+T20)*U20+V20 -> 516.05 | X20: Milano | Y20: Fineco-C | Z20: {=_FV(M20,"Price",TRUE)} -> 70.96 | AA20: =SUMIF(Operazioni!A:A,A20,Operazioni!C:C) -> 0 | AB20: =INDEX(Valute!B:B,MATCH(J20,Valute!A:A,0)) -> 1 | AC20: =SUMIF(Operazioni!A:A,A20,Operazioni!K:K) -> 24.938 | AD20: =((I20+AA20)/IF(OR(D20="O",D20="CE"),100,1)*Z20)*AB20+AC20 -> 734.538 | AE20: =AD20-W20 -> 218.488 | AF20: =IF(W20<>0,AE20/W20,"") -> 0.42338533 | AG20: 45992 | AH20: Milano | AI20: Fineco-C | AJ20: 63.96 | AL20: 2.95 | AM20: 1 | AO20: =AC20*(1-N20) -> 18.45412 | AP20: =((I20+AA20)/IF(OR(D20="O",D20="CE"),100,1)*AJ20*(1-AK20)-AL20)*AM20-AN20+AC20 -> 661.588 | AQ20: =AP20-W20 -> 145.538 | AR20: =IF(W20<>0,AQ20/W20,"") -> 0.28202306 | AS20: =(AQ20-AC20)*N20 -> 31.356 | AT20: =IF(W20<>0,(AQ20-AS20)/W20,"") -> 0.22126151
A21: 4 | B21: 1 | C21: iShares Global Clean Energy UCITS ETF USD (Dist) | D21: ETF | E21: Azioni | F21: Mondo | G21: Energia | H21: iShares | I21: 50 | J21: EUR | K21: IE00B1XNHC34 | L21: INRG.MI | M21: #VALUE! | N21: 0.26 | O21: 45112 | P21: Milano | Q21: Fineco-C | R21: 9.635 | S21: 0 | T21: 0 | U21: 1 | V21: 2.95 | W21: =(I21/IF(OR(D21="O",D21="CE"),100,1)*R21*(1+S21)+T21)*U21+V21 -> 484.7 | X21: Milano | Y21: Fineco-C | Z21: 7.4341 | AA21: =SUMIF(Operazioni!A:A,A21,Operazioni!C:C) -> 0 | AB21: =INDEX(Valute!B:B,MATCH(J21,Valute!A:A,0)) -> 1 | AC21: =SUMIF(Operazioni!A:A,A21,Operazioni!K:K) -> 2.3532 | AD21: =((I21+AA21)/IF(OR(D21="O",D21="CE"),100,1)*Z21)*AB21+AC21 -> 374.0582 | AE21: =AD21-W21 -> -110.6418 | AF21: =IF(W21<>0,AE21/W21,"") -> -0.22826862 | AG21: 45531 | AH21: Milano | AI21: Fineco-C | AJ21: 7.43412 | AK21: 0.0072 | AL21: 2.95 | AM21: 1 | AO21: =AC21*(1-N21) -> 1.741368 | AP21: =((I21+AA21)/IF(OR(D21="O",D21="CE"),100,1)*AJ21*(1-AK21)-AL21)*AM21-AN21+AC21 -> 368.43292 | AQ21: =AP21-W21 -> -116.26708 | AR21: =IF(W21<>0,AQ21/W21,"") -> -0.23987432 | AS21: =(AQ21-AC21)*N21 -> -30.841274 | AT21: =IF(W21<>0,(AQ21-AS21)/W21,"") -> -0.17624471
A22: 5 | B22: 1 | C22: iShares Core S&P 500 UCITS ETF USD (Dist) | D22: ETF | E22: Azioni | F22: US | H22: iShares | I22: 10 | J22: EUR | K22: IE0031442068 | L22: IUSA.MI | M22: #VALUE! | N22: 0.26 | O22: 45112 | P22: Milano | Q22: Fineco-C | R22: 40.63 | S22: 0 | T22: 0 | U22: 1 | V22: 2.95 | W22: =(I22/IF(OR(D22="O",D22="CE"),100,1)*R22*(1+S22)+T22)*U22+V22 -> 409.25 | X22: Milano | Y22: Fineco-C | Z22: {=_FV(M22,"Price",TRUE)} -> 64.45 | AA22: =SUMIF(Operazioni!A:A,A22,Operazioni!C:C) -> 0 | AB22: =INDEX(Valute!B:B,MATCH(J22,Valute!A:A,0)) -> 1 | AC22: =SUMIF(Operazioni!A:A,A22,Operazioni!K:K) -> 14.07332 | AD22: =((I22+AA22)/IF(OR(D22="O",D22="CE"),100,1)*Z22)*AB22+AC22 -> 658.57332 | AE22: =AD22-W22 -> 249.32332 | AF22: =IF(W22<>0,AE22/W22,"") -> 0.60922009 | AG22: 45992 | AH22: Milano | AI22: Fineco-C | AJ22: 58.51 | AL22: 2.95 | AM22: 1 | AO22: =AC22*(1-N22) -> 10.414257 | AP22: =((I22+AA22)/IF(OR(D22="O",D22="CE"),100,1)*AJ22*(1-AK22)-AL22)*AM22-AN22+AC22 -> 596.22332 | AQ22: =AP22-W22 -> 186.97332 | AR22: =IF(W22<>0,AQ22/W22,"") -> 0.45686822 | AS22: =(AQ22-AC22)*N22 -> 44.954 | AT22: =IF(W22<>0,(AQ22-AS22)/W22,"") -> 0.34702338
A23: 6 | B23: 1 | C23: iShares Core S&P 500 UCITS ETF USD (Dist) | D23: ETF | E23: Azioni | F23: US | H23: iShares | I23: 15 | J23: EUR | K23: IE0031442068 | L23: IUSA.MI | M23: #VALUE! | N23: 0.26 | O23: 45128 | P23: Milano | Q23: Fineco-C | R23: 40.7 | S23: 0 | T23: 0 | U23: 1 | V23: 2.95 | W23: =(I23/IF(OR(D23="O",D23="CE"),100,1)*R23*(1+S23)+T23)*U23+V23 -> 613.45 | X23: Milano | Y23: Fineco-C | Z23: {=_FV(M23,"Price",TRUE)} -> 64.45 | AA23: =SUMIF(Operazioni!A:A,A23,Operazioni!C:C) -> 0 | AB23: =INDEX(Valute!B:B,MATCH(J23,Valute!A:A,0)) -> 1 | AC23: =SUMIF(Operazioni!A:A,A23,Operazioni!K:K) -> 9.02948 | AD23: =((I23+AA23)/IF(OR(D23="O",D23="CE"),100,1)*Z23)*AB23+AC23 -> 975.77948 | AE23: =AD23-W23 -> 362.32948 | AF23: =IF(W23<>0,AE23/W23,"") -> 0.59064224 | AG23: 45992 | AH23: Milano | AI23: Fineco-C | AJ23: 58.51 | AL23: 2.95 | AM23: 1 | AO23: =AC23*(1-N23) -> 6.6818152 | AP23: =((I23+AA23)/IF(OR(D23="O",D23="CE"),100,1)*AJ23*(1-AK23)-AL23)*AM23-AN23+AC23 -> 883.72948 | AQ23: =AP23-W23 -> 270.27948 | AR23: =IF(W23<>0,AQ23/W23,"") -> 0.44058926 | AS23: =(AQ23-AC23)*N23 -> 67.925 | AT23: =IF(W23<>0,(AQ23-AS23)/W23,"") -> 0.32986304
A24: 7 | B24: 1 | C24: Amundi MSCI Semiconductors ESG Screened UCITS ETF Acc | D24: ETF | E24: Azioni | F24: Mondo | G24: Tecnologia | H24: Amundi | I24: 20 | J24: EUR | K24: LU1900066033 | L24: CHIP.MI | M24: #VALUE! | N24: 0.26 | O24: 45124 | P24: Milano | Q24: Fineco-C | R24: 28.41 | S24: 0 | T24: 0 | U24: 1 | W24: =(I24/IF(OR(D24="O",D24="CE"),100,1)*R24*(1+S24)+T24)*U24+V24 -> 568.2 | X24: Milano | Y24: Fineco-C | Z24: 57 | AA24: =SUMIF(Operazioni!A:A,A24,Operazioni!C:C) -> 0 | AB24: =INDEX(Valute!B:B,MATCH(J24,Valute!A:A,0)) -> 1 | AC24: =SUMIF(Operazioni!A:A,A24,Operazioni!K:K) -> 0 | AD24: =((I24+AA24)/IF(OR(D24="O",D24="CE"),100,1)*Z24)*AB24+AC24 -> 1140 | AE24: =AD24-W24 -> 571.8 | AF24: =IF(W24<>0,AE24/W24,"") -> 1.0063358 | AG24: 45663 | AH24: Milano | AI24: Fineco-C | AJ24: 57 | AL24: 2.95 | AM24: 1 | AO24: =AC24*(1-N24) -> 0 | AP24: =((I24+AA24)/IF(OR(D24="O",D24="CE"),100,1)*AJ24*(1-AK24)-AL24)*AM24-AN24+AC24 -> 1137.05 | AQ24: =AP24-W24 -> 568.85 | AR24: =IF(W24<>0,AQ24/W24,"") -> 1.001144 | AS24: =(AQ24-AC24)*N24 -> 147.901 | AT24: =IF(W24<>0,(AQ24-AS24)/W24,"") -> 0.74084653
A25: 8 | B25: 1 | C25: Xtrackers Artif. Int. and Big Data UCITS ETF 1C | D25: ETF | E25: Azioni | F25: US | G25: Tecnologia | H25: Xtrackers | I25: 6 | J25: EUR | K25: IE00BGV5VN51 | L25: XAIX.MI | M25: #VALUE! | N25: 0.26 | O25: 45128 | P25: Milano | Q25: Fineco-C | R25: 87 | S25: 0 | T25: 0 | U25: 1 | V25: 2.95 | W25: =(I25/IF(OR(D25="O",D25="CE"),100,1)*R25*(1+S25)+T25)*U25+V25 -> 524.95 | X25: Milano | Y25: Fineco-C | Z25: {=_FV(M25,"Price",TRUE)} -> 200.84 | AA25: =SUMIF(Operazioni!A:A,A25,Operazioni!C:C) -> 0 | AB25: =INDEX(Valute!B:B,MATCH(J25,Valute!A:A,0)) -> 1 | AC25: =SUMIF(Operazioni!A:A,A25,Operazioni!K:K) -> 0 | AD25: =((I25+AA25)/IF(OR(D25="O",D25="CE"),100,1)*Z25)*AB25+AC25 -> 1205.04 | AE25: =AD25-W25 -> 680.09 | AF25: =IF(W25<>0,AE25/W25,"") -> 1.2955329 | AG25: 46156 | AH25: Milano | AI25: Fineco-C | AJ25: 193.7 | AL25: 2.95 | AM25: 1 | AO25: =AC25*(1-N25) -> 0 | AP25: =((I25+AA25)/IF(OR(D25="O",D25="CE"),100,1)*AJ25*(1-AK25)-AL25)*AM25-AN25+AC25 -> 1159.25 | AQ25: =AP25-W25 -> 634.3 | AR25: =IF(W25<>0,AQ25/W25,"") -> 1.2083056 | AS25: =(AQ25-AC25)*N25 -> 164.918 | AT25: =IF(W25<>0,(AQ25-AS25)/W25,"") -> 0.89414611
A26: 9 | B26: 1 | C26: iShares Core MSCI Europe UCITS ETF EUR (Acc) | D26: ETF | E26: Azioni | F26: EU | H26: iShares | I26: 14 | J26: EUR | K26: IE00B4K48X80 | L26: SMEA.MI | M26: #VALUE! | N26: 0.26 | O26: 45128 | P26: Milano | Q26: Fineco-C | R26: 69.25 | S26: 0 | T26: 0 | U26: 1 | V26: 2.95 | W26: =(I26/IF(OR(D26="O",D26="CE"),100,1)*R26*(1+S26)+T26)*U26+V26 -> 972.45 | X26: Milano | Y26: Fineco-C | Z26: {=_FV(M26,"Price",TRUE)} -> 101.64 | AA26: =SUMIF(Operazioni!A:A,A26,Operazioni!C:C) -> 0 | AB26: =INDEX(Valute!B:B,MATCH(J26,Valute!A:A,0)) -> 1 | AC26: =SUMIF(Operazioni!A:A,A26,Operazioni!K:K) -> 0 | AD26: =((I26+AA26)/IF(OR(D26="O",D26="CE"),100,1)*Z26)*AB26+AC26 -> 1422.96 | AE26: =AD26-W26 -> 450.51 | AF26: =IF(W26<>0,AE26/W26,"") -> 0.46327318 | AO26: =AC26*(1-N26) -> 0 | AP26: =((I26+AA26)/IF(OR(D26="O",D26="CE"),100,1)*AJ26*(1-AK26)-AL26)*AM26-AN26+AC26 -> 0 | AQ26: =AP26-W26 -> -972.45 | AR26: =IF(W26<>0,AQ26/W26,"") -> -1 | AS26: =(AQ26-AC26)*N26 -> -252.837 | AT26: =IF(W26<>0,(AQ26-AS26)/W26,"") -> -0.74
A27: 24 | B27: 1 | C27: Vanguard FTSE All-World UCITS ETF (USD) Acc | D27: ETF | E27: Azioni | F27: Mondo | H27: Vanguard | I27: 10 | J27: EUR | K27: IE00BK5BQT80 | L27: VWCE.MI | M27: #VALUE! | N27: 0.26 | O27: 45161 | P27: Milano | Q27: Fineco-C | R27: 100.5 | S27: 0 | T27: 0 | U27: 1 | V27: 2.95 | W27: =(I27/IF(OR(D27="O",D27="CE"),100,1)*R27*(1+S27)+T27)*U27+V27 -> 1007.95 | X27: Milano | Y27: Fineco-C | Z27: {=_FV(M27,"Price",TRUE)} -> 162.56 | AA27: =SUMIF(Operazioni!A:A,A27,Operazioni!C:C) -> 0 | AB27: =INDEX(Valute!B:B,MATCH(J27,Valute!A:A,0)) -> 1 | AC27: =SUMIF(Operazioni!A:A,A27,Operazioni!K:K) -> 0 | AD27: =((I27+AA27)/IF(OR(D27="O",D27="CE"),100,1)*Z27)*AB27+AC27 -> 1625.6 | AE27: =AD27-W27 -> 617.65 | AF27: =IF(W27<>0,AE27/W27,"") -> 0.61277841 | AO27: =AC27*(1-N27) -> 0 | AP27: =((I27+AA27)/IF(OR(D27="O",D27="CE"),100,1)*AJ27*(1-AK27)-AL27)*AM27-AN27+AC27 -> 0 | AQ27: =AP27-W27 -> -1007.95 | AR27: =IF(W27<>0,AQ27/W27,"") -> -1 | AS27: =(AQ27-AC27)*N27 -> -262.067 | AT27: =IF(W27<>0,(AQ27-AS27)/W27,"") -> -0.74
A28: 27 | B28: 1 | C28: Vanguard FTSE All-World UCITS ETF (USD) Acc | D28: ETF | E28: Azioni | F28: Mondo | H28: Vanguard | I28: 60 | J28: EUR | K28: IE00BK5BQT80 | L28: VWCE.MI | M28: #VALUE! | N28: 0.26 | O28: 45162 | P28: Milano | Q28: Fineco-C | R28: 101.3 | S28: 0.0019 | T28: 0 | U28: 1 | V28: 2.95 | W28: =(I28/IF(OR(D28="O",D28="CE"),100,1)*R28*(1+S28)+T28)*U28+V28 -> 6092.4982 | X28: Milano | Y28: Fineco-C | Z28: {=_FV(M28,"Price")} -> 162.56 | AA28: =SUMIF(Operazioni!A:A,A28,Operazioni!C:C) -> 0 | AB28: =INDEX(Valute!B:B,MATCH(J28,Valute!A:A,0)) -> 1 | AC28: =SUMIF(Operazioni!A:A,A28,Operazioni!K:K) -> 0 | AD28: =((I28+AA28)/IF(OR(D28="O",D28="CE"),100,1)*Z28)*AB28+AC28 -> 9753.6 | AE28: =AD28-W28 -> 3661.1018 | AF28: =IF(W28<>0,AE28/W28,"") -> 0.60091964 | AO28: =AC28*(1-N28) -> 0 | AP28: =((I28+AA28)/IF(OR(D28="O",D28="CE"),100,1)*AJ28*(1-AK28)-AL28)*AM28-AN28+AC28 -> 0 | AQ28: =AP28-W28 -> -6092.4982 | AR28: =IF(W28<>0,AQ28/W28,"") -> -1 | AS28: =(AQ28-AC28)*N28 -> -1584.0495 | AT28: =IF(W28<>0,(AQ28-AS28)/W28,"") -> -0.74
A29: 28 | B29: 1 | C29: Vanguard FTSE All-World UCITS ETF (USD) Acc | D29: ETF | E29: Azioni | F29: Mondo | H29: Vanguard | I29: 30 | J29: EUR | K29: IE00BK5BQT80 | L29: VWCE.MI | M29: #VALUE! | N29: 0.26 | O29: 45163 | P29: Milano | Q29: Fineco-C | R29: 100.5 | S29: 0.0019 | T29: 0 | U29: 1 | V29: 2.95 | W29: =(I29/IF(OR(D29="O",D29="CE"),100,1)*R29*(1+S29)+T29)*U29+V29 -> 3023.6785 | X29: Milano | Y29: Fineco-C | Z29: {=_FV(M29,"Price")} -> 162.56 | AA29: =SUMIF(Operazioni!A:A,A29,Operazioni!C:C) -> 0 | AB29: =INDEX(Valute!B:B,MATCH(J29,Valute!A:A,0)) -> 1 | AC29: =SUMIF(Operazioni!A:A,A29,Operazioni!K:K) -> 0 | AD29: =((I29+AA29)/IF(OR(D29="O",D29="CE"),100,1)*Z29)*AB29+AC29 -> 4876.8 | AE29: =AD29-W29 -> 1853.1215 | AF29: =IF(W29<>0,AE29/W29,"") -> 0.61286989 | AO29: =AC29*(1-N29) -> 0 | AP29: =((I29+AA29)/IF(OR(D29="O",D29="CE"),100,1)*AJ29*(1-AK29)-AL29)*AM29-AN29+AC29 -> 0 | AQ29: =AP29-W29 -> -3023.6785 | AR29: =IF(W29<>0,AQ29/W29,"") -> -1 | AS29: =(AQ29-AC29)*N29 -> -786.15641 | AT29: =IF(W29<>0,(AQ29-AS29)/W29,"") -> -0.74
A30: 32 | B30: 1 | C30: Vanguard FTSE All-World UCITS ETF (USD) Acc | D30: ETF | E30: Azioni | F30: Mondo | H30: Vanguard | I30: 20 | J30: EUR | K30: IE00BK5BQT80 | L30: VWCE.MI | M30: #VALUE! | N30: 0.26 | O30: 45302 | P30: Milano | Q30: Fineco | R30: 107.14 | S30: 0 | T30: 0 | U30: 1 | V30: 19 | W30: =(I30/IF(OR(D30="O",D30="CE"),100,1)*R30*(1+S30)+T30)*U30+V30 -> 2161.8 | X30: Milano | Y30: Fineco | Z30: {=_FV(M30,"Price",TRUE)} -> 162.56 | AA30: =SUMIF(Operazioni!A:A,A30,Operazioni!C:C) -> 0 | AB30: =INDEX(Valute!B:B,MATCH(J30,Valute!A:A,0)) -> 1 | AC30: =SUMIF(Operazioni!A:A,A30,Operazioni!K:K) -> 0 | AD30: =((I30+AA30)/IF(OR(D30="O",D30="CE"),100,1)*Z30)*AB30+AC30 -> 3251.2 | AE30: =AD30-W30 -> 1089.4 | AF30: =IF(W30<>0,AE30/W30,"") -> 0.50393191 | AO30: =AC30*(1-N30) -> 0 | AP30: =((I30+AA30)/IF(OR(D30="O",D30="CE"),100,1)*AJ30*(1-AK30)-AL30)*AM30-AN30+AC30 -> 0 | AQ30: =AP30-W30 -> -2161.8 | AR30: =IF(W30<>0,AQ30/W30,"") -> -1 | AS30: =(AQ30-AC30)*N30 -> -562.068 | AT30: =IF(W30<>0,(AQ30-AS30)/W30,"") -> -0.74
A31: 10 | B31: 1 | C31: BTP-VAL 13GN27SU CUM | D31: O | E31: Obblig | F31: Italia | G31: Governativo | H31: Italia | I31: 10000 | J31: EUR | K31: IT0005547408 | N31: 0.125 | O31: 45083 | P31: MOT | Q31: Fineco-C | R31: 100 | S31: 0 | T31: 0 | U31: 1 | W31: =(I31/IF(OR(D31="O",D31="CE"),100,1)*R31*(1+S31)+T31)*U31+V31 -> 10000 | X31: MOT | Y31: Fineco-C | Z31: 100 | AA31: =SUMIF(Operazioni!A:A,A31,Operazioni!C:C) -> 0 | AB31: =INDEX(Valute!B:B,MATCH(J31,Valute!A:A,0)) -> 1 | AC31: =SUMIF(Operazioni!A:A,A31,Operazioni!K:K) -> 743.75 | AD31: =((I31+AA31)/IF(OR(D31="O",D31="CE"),100,1)*Z31)*AB31+AC31 -> 10743.75 | AE31: =AD31-W31 -> 743.75002 | AF31: =IF(W31<>0,AE31/W31,"") -> 0.074375002 | AO31: =AC31*(1-N31) -> 650.78125 | AP31: =((I31+AA31)/IF(OR(D31="O",D31="CE"),100,1)*AJ31*(1-AK31)-AL31)*AM31-AN31+AC31 -> 743.75 | AQ31: =AP31-W31 -> -9256.25 | AR31: =IF(W31<>0,AQ31/W31,"") -> -0.925625 | AS31: =(AQ31-AC31)*N31 -> -1250 | AT31: =IF(W31<>0,(AQ31-AS31)/W31,"") -> -0.800625
A32: 11 | B32: 1 | C32: USA-15FB26 6 | D32: O | E32: Obblig | F32: US | G32: Governativo | H32: US | I32: 5000 | J32: USD | K32: US912810EW46 | N32: 0.125 | O32: 45128 | P32: ETLX | Q32: Fineco-C | R32: 103.39 | S32: 0.005 | T32: 0 | U32: 0.9017 | V32: 82.57 | W32: =(I32/IF(OR(D32="O",D32="CE"),100,1)*R32*(1+S32)+T32)*U32+V32 -> 4767.2148 | X32: ETLX | Y32: Fineco-C | Z32: 100 | AA32: =SUMIF(Operazioni!A:A,A32,Operazioni!C:C) -> 0 | AB32: =INDEX(Valute!B:B,MATCH(J32,Valute!A:A,0)) -> 0.86002565 | AC32: =SUMIF(Operazioni!A:A,A32,Operazioni!K:K) -> 710.55323 | AD32: =((I32+AA32)/IF(OR(D32="O",D32="CE"),100,1)*Z32)*AB32+AC32 -> 5010.6815 | AE32: =AD32-W32 -> 243.46664 | AF32: =IF(W32<>0,AE32/W32,"") -> 0.051071043 | AG32: 46070 | AH32: Milano | AI32: Fineco-C | AJ32: 100 | AM32: 0.8437 | AO32: =AC32*(1-N32) -> 621.73407 | AP32: =((I32+AA32)/IF(OR(D32="O",D32="CE"),100,1)*AJ32*(1-AK32)-AL32)*AM32-AN32+AC32 -> 4929.0532 | AQ32: =AP32-W32 -> 161.83839 | AR32: =IF(W32<>0,AQ32/W32,"") -> 0.033948205 | AS32: =(AQ32-AC32)*N32 -> -68.589355 | AT32: =IF(W32<>0,(AQ32-AS32)/W32,"") -> 0.048335925
A33: 12 | B33: 1 | C33: BTP-1OT53 4,5 | D33: O | E33: Obblig | F33: Italia | G33: Governativo | H33: Italia | I33: 5000 | J33: EUR | K33: IT0005534141 | N33: 0.125 | O33: 45128 | P33: MOT | Q33: Fineco-C | R33: 100.67 | S33: 0.0019 | T33: 0 | U33: 1 | V33: 61.82 | W33: =(I33/IF(OR(D33="O",D33="CE"),100,1)*R33*(1+S33)+T33)*U33+V33 -> 5104.8836 | X33: MOT | Y33: Fineco-C | Z33: 100 | AA33: =SUMIF(Operazioni!A:A,A33,Operazioni!C:C) -> 0 | AB33: =INDEX(Valute!B:B,MATCH(J33,Valute!A:A,0)) -> 1 | AC33: =SUMIF(Operazioni!A:A,A33,Operazioni!K:K) -> 590.625 | AD33: =((I33+AA33)/IF(OR(D33="O",D33="CE"),100,1)*Z33)*AB33+AC33 -> 5590.625 | AE33: =AD33-W33 -> 485.74136 | AF33: =IF(W33<>0,AE33/W33,"") -> 0.095152288 | AO33: =AC33*(1-N33) -> 516.79688 | AP33: =((I33+AA33)/IF(OR(D33="O",D33="CE"),100,1)*AJ33*(1-AK33)-AL33)*AM33-AN33+AC33 -> 590.625 | AQ33: =AP33-W33 -> -4514.2586 | AR33: =IF(W33<>0,AQ33/W33,"") -> -0.88430197 | AS33: =(AQ33-AC33)*N33 -> -638.11046 | AT33: =IF(W33<>0,(AQ33-AS33)/W33,"") -> -0.75930197
A34: 25 | B34: 1 | C34: BTP-29ST25 3,60 | D34: O | E34: Obblig | F34: Italia | G34: Governativo | H34: Italia | I34: 5000 | J34: EUR | K34: IT0005557084 | N34: 0.125 | O34: 45161 | P34: MOT | Q34: Fineco-C | R34: 99.99 | S34: 0.0019 | T34: 0 | U34: 1 | V34: 12.39 | W34: =(I34/IF(OR(D34="O",D34="CE"),100,1)*R34*(1+S34)+T34)*U34+V34 -> 5021.3891 | X34: MOT | Y34: Fineco-C | Z34: 100 | AA34: =SUMIF(Operazioni!A:A,A34,Operazioni!C:C) -> 0 | AB34: =INDEX(Valute!B:B,MATCH(J34,Valute!A:A,0)) -> 1 | AC34: =SUMIF(Operazioni!A:A,A34,Operazioni!K:K) -> 342.3875 | AD34: =((I34+AA34)/IF(OR(D34="O",D34="CE"),100,1)*Z34)*AB34+AC34 -> 5342.3875 | AE34: =AD34-W34 -> 320.99846 | AF34: =IF(W34<>0,AE34/W34,"") -> 0.063926228 | AG34: 45929 | AH34: Milano | AI34: Fineco-C | AJ34: 100 | AM34: 1 | AO34: =AC34*(1-N34) -> 299.58906 | AP34: =((I34+AA34)/IF(OR(D34="O",D34="CE"),100,1)*AJ34*(1-AK34)-AL34)*AM34-AN34+AC34 -> 5342.3875 | AQ34: =AP34-W34 -> 320.99845 | AR34: =IF(W34<>0,AQ34/W34,"") -> 0.063926226 | AS34: =(AQ34-AC34)*N34 -> -2.6736313 | AT34: =IF(W34<>0,(AQ34-AS34)/W34,"") -> 0.064458674
A35: 26 | B35: 1 | C35: USA-15MG25 2,125 | D35: O | E35: Obblig | F35: US | G35: Governativo | H35: US | I35: 5000 | J35: USD | K35: US912828XB14 | N35: 0.125 | O35: 45161 | P35: ETLX | Q35: Fineco-C | R35: 95.17 | S35: 0.005 | T35: 0 | U35: 0.9184 | V35: 52.51 | W35: =(I35/IF(OR(D35="O",D35="CE"),100,1)*R35*(1+S35)+T35)*U35+V35 -> 4444.5674 | X35: ETLX | Y35: Fineco-C | Z35: 100 | AA35: =SUMIF(Operazioni!A:A,A35,Operazioni!C:C) -> 0 | AB35: =INDEX(Valute!B:B,MATCH(J35,Valute!A:A,0)) -> 0.86002565 | AC35: =SUMIF(Operazioni!A:A,A35,Operazioni!K:K) -> 171.0275 | AD35: =((I35+AA35)/IF(OR(D35="O",D35="CE"),100,1)*Z35)*AB35+AC35 -> 4471.1557 | AE35: =AD35-W35 -> 26.588318 | AF35: =IF(W35<>0,AE35/W35,"") -> 0.005982206 | AG35: 45792 | AH35: Milano | AI35: Fineco-C | AJ35: 100 | AM35: =1/1.1185 -> 0.89405454 | AO35: =AC35*(1-N35) -> 149.64906 | AP35: =((I35+AA35)/IF(OR(D35="O",D35="CE"),100,1)*AJ35*(1-AK35)-AL35)*AM35-AN35+AC35 -> 4641.3002 | AQ35: =AP35-W35 -> 196.73275 | AR35: =IF(W35<>0,AQ35/W35,"") -> 0.044263645 | AS35: =(AQ35-AC35)*N35 -> 3.2131568 | AT35: =IF(W35<>0,(AQ35-AS35)/W35,"") -> 0.043540705
A36: 29 | B36: 1 | C36: BTP-VAL 10OT28SU CUM | D36: O | E36: Obblig | F36: Italia | G36: Governativo | H36: Italia | I36: 5000 | J36: EUR | K36: IT0005565400 | N36: 0.125 | O36: 45201 | P36: MOT | Q36: Fineco | R36: 100 | S36: 0 | T36: 0 | U36: 1 | W36: =(I36/IF(OR(D36="O",D36="CE"),100,1)*R36*(1+S36)+T36)*U36+V36 -> 5000 | X36: MOT | Y36: Fineco | Z36: 100 | AA36: =SUMIF(Operazioni!A:A,A36,Operazioni!C:C) -> 0 | AB36: =INDEX(Valute!B:B,MATCH(J36,Valute!A:A,0)) -> 1 | AC36: =SUMIF(Operazioni!A:A,A36,Operazioni!K:K) -> 403.59375 | AD36: =((I36+AA36)/IF(OR(D36="O",D36="CE"),100,1)*Z36)*AB36+AC36 -> 5403.5938 | AE36: =AD36-W36 -> 403.59376 | AF36: =IF(W36<>0,AE36/W36,"") -> 0.080718752 | AO36: =AC36*(1-N36) -> 353.14453 | AP36: =((I36+AA36)/IF(OR(D36="O",D36="CE"),100,1)*AJ36*(1-AK36)-AL36)*AM36-AN36+AC36 -> 403.59375 | AQ36: =AP36-W36 -> -4596.4062 | AR36: =IF(W36<>0,AQ36/W36,"") -> -0.91928125 | AS36: =(AQ36-AC36)*N36 -> -625 | AT36: =IF(W36<>0,(AQ36-AS36)/W36,"") -> -0.79428125
A37: 31 | B37: 1 | C37: SPAIN-30LG33 2,35 | D37: O | E37: Obblig | F37: EU | G37: Governativo | H37: Spagna | I37: 2000 | J37: EUR | K37: ES00000128Q6 | N37: 0.125 | O37: 45302 | P37: MOT | Q37: Fineco | R37: 94.04 | S37: 0 | T37: 0 | U37: 1 | V37: 19 | W37: =(I37/IF(OR(D37="O",D37="CE"),100,1)*R37*(1+S37)+T37)*U37+V37 -> 1899.8 | X37: MOT | Y37: Fineco | Z37: 100 | AA37: =SUMIF(Operazioni!A:A,A37,Operazioni!C:C) -> 0 | AB37: =INDEX(Valute!B:B,MATCH(J37,Valute!A:A,0)) -> 1 | AC37: =SUMIF(Operazioni!A:A,A37,Operazioni!K:K) -> 82.25 | AD37: =((I37+AA37)/IF(OR(D37="O",D37="CE"),100,1)*Z37)*AB37+AC37 -> 2082.25 | AE37: =AD37-W37 -> 182.45 | AF37: =IF(W37<>0,AE37/W37,"") -> 0.096036427 | AO37: =AC37*(1-N37) -> 71.96875 | AP37: =((I37+AA37)/IF(OR(D37="O",D37="CE"),100,1)*AJ37*(1-AK37)-AL37)*AM37-AN37+AC37 -> 82.25 | AQ37: =AP37-W37 -> -1817.55 | AR37: =IF(W37<>0,AQ37/W37,"") -> -0.95670597 | AS37: =(AQ37-AC37)*N37 -> -237.475 | AT37: =IF(W37<>0,(AQ37-AS37)/W37,"") -> -0.83170597
A38: 33 | B38: 1 | C38: BTP-VAL 5MZ30SU CUM | D38: O | E38: Obblig | F38: Italia | G38: Governativo | H38: Italia | I38: 2000 | J38: EUR | K38: IT0005583486 | N38: 0.125 | O38: 45350 | P38: MOT | Q38: Fineco | R38: 100 | S38: 0 | T38: 0 | U38: 1 | W38: =(I38/IF(OR(D38="O",D38="CE"),100,1)*R38*(1+S38)+T38)*U38+V38 -> 2000 | X38: MOT | Y38: Fineco | Z38: 100 | AA38: =SUMIF(Operazioni!A:A,A38,Operazioni!C:C) -> 0 | AB38: =INDEX(Valute!B:B,MATCH(J38,Valute!A:A,0)) -> 1 | AC38: =SUMIF(Operazioni!A:A,A38,Operazioni!K:K) -> 113.75 | AD38: =((I38+AA38)/IF(OR(D38="O",D38="CE"),100,1)*Z38)*AB38+AC38 -> 2113.75 | AE38: =AD38-W38 -> 113.75 | AF38: =IF(W38<>0,AE38/W38,"") -> 0.056875002 | AO38: =AC38*(1-N38) -> 99.53125 | AP38: =((I38+AA38)/IF(OR(D38="O",D38="CE"),100,1)*AJ38*(1-AK38)-AL38)*AM38-AN38+AC38 -> 113.75 | AQ38: =AP38-W38 -> -1886.25 | AR38: =IF(W38<>0,AQ38/W38,"") -> -0.943125 | AS38: =(AQ38-AC38)*N38 -> -250 | AT38: =IF(W38<>0,(AQ38-AS38)/W38,"") -> -0.818125
A39: 34 | B39: 1 | C39: Vanguard FTSE All-World UCITS ETF (USD) Acc | D39: ETF | E39: Azioni | F39: Mondo | H39: Vanguard | I39: 9 | J39: EUR | K39: IE00BK5BQT80 | L39: VWCE.MI | M39: #VALUE! | N39: 0.26 | O39: 45427 | P39: Milano | Q39: Fineco | R39: 118.934 | S39: 0 | T39: 0 | U39: 1 | V39: 2.95 | W39: =(I39/IF(OR(D39="O",D39="CE"),100,1)*R39*(1+S39)+T39)*U39+V39 -> 1073.356 | X39: Milano | Y39: Fineco | Z39: {=_FV(M39,"Price",TRUE)} -> 162.56 | AA39: =SUMIF(Operazioni!A:A,A39,Operazioni!C:C) -> 0 | AB39: =INDEX(Valute!B:B,MATCH(J39,Valute!A:A,0)) -> 1 | AC39: =SUMIF(Operazioni!A:A,A39,Operazioni!K:K) -> 0 | AD39: =((I39+AA39)/IF(OR(D39="O",D39="CE"),100,1)*Z39)*AB39+AC39 -> 1463.04 | AE39: =AD39-W39 -> 389.684 | AF39: =IF(W39<>0,AE39/W39,"") -> 0.36305196 | AO39: =AC39*(1-N39) -> 0 | AP39: =((I39+AA39)/IF(OR(D39="O",D39="CE"),100,1)*AJ39*(1-AK39)-AL39)*AM39-AN39+AC39 -> 0 | AQ39: =AP39-W39 -> -1073.356 | AR39: =IF(W39<>0,AQ39/W39,"") -> -1 | AS39: =(AQ39-AC39)*N39 -> -279.07256 | AT39: =IF(W39<>0,(AQ39-AS39)/W39,"") -> -0.74
A40: 35 | B40: 1 | C40: Invesco Physical Gold ETC | D40: ETF | E40: Oro | F40: US | G40: Siderurgia | H40: Invesco | I40: 10 | J40: EUR | K40: IE00B579F325 | L40: SGLD.MI | M40: #VALUE! | N40: 0.26 | O40: 45439 | P40: Milano | Q40: Fineco | R40: 208.4 | S40: 0 | T40: 0 | U40: 1 | V40: 19 | W40: =(I40/IF(OR(D40="O",D40="CE"),100,1)*R40*(1+S40)+T40)*U40+V40 -> 2103 | X40: Milano | Y40: Fineco | Z40: {=_FV(M40,"Price",TRUE)} -> 372.88 | AA40: =SUMIF(Operazioni!A:A,A40,Operazioni!C:C) -> 0 | AB40: =INDEX(Valute!B:B,MATCH(J40,Valute!A:A,0)) -> 1 | AC40: =SUMIF(Operazioni!A:A,A40,Operazioni!K:K) -> 0 | AD40: =((I40+AA40)/IF(OR(D40="O",D40="CE"),100,1)*Z40)*AB40+AC40 -> 3728.8 | AE40: =AD40-W40 -> 1625.8 | AF40: =IF(W40<>0,AE40/W40,"") -> 0.77308607 | AO40: =AC40*(1-N40) -> 0 | AP40: =((I40+AA40)/IF(OR(D40="O",D40="CE"),100,1)*AJ40*(1-AK40)-AL40)*AM40-AN40+AC40 -> 0 | AQ40: =AP40-W40 -> -2103 | AR40: =IF(W40<>0,AQ40/W40,"") -> -1 | AS40: =(AQ40-AC40)*N40 -> -546.78 | AT40: =IF(W40<>0,(AQ40-AS40)/W40,"") -> -0.74
...

Sheet Operazioni
A1: ID | B1: Data | C1: Variazione quantità | D1: Dividendi valuta | E1: Cambio | F1: Dividendi euro | G1: Valuta | H1: Dividendi lordi | I1: Tassazione | J1: Tasse | K1: Dividendi totali netti euro | L1: Note
A2: 21 | B2: 44430 | E2: 1 | F2: 0.38 | G2: =INDEX('Stato patrimoniale'!J:J,MATCH(A2,'Stato patrimoniale'!A:A,0)) -> USD | H2: =F2+D2*E2 -> 0.38 | I2: =INDEX('Stato patrimoniale'!N:N,MATCH(A2,'Stato patrimoniale'!A:A,0)) -> 0.26 | J2: =H2*I2 -> 0.0988 | K2: =H2-(H2*I2) -> 0.2812 | M2: Totale lordo: | N2: =SUM(H2:H1002) -> 5225.5508
A3: 23 | B3: 44452 | E3: 1 | F3: 29.09 | G3: =INDEX('Stato patrimoniale'!J:J,MATCH(A3,'Stato patrimoniale'!A:A,0)) -> USD | H3: =F3+D3*E3 -> 29.09 | I3: =INDEX('Stato patrimoniale'!N:N,MATCH(A3,'Stato patrimoniale'!A:A,0)) -> 0.26 | J3: =H3*I3 -> 7.5634 | K3: =H3-(H3*I3) -> 21.5266 | M3: Totale netto: | N3: =SUM(K2:K1002) -> 4409.5011
A4: 21 | B4: 44516 | E4: 1 | F4: 0.33 | G4: =INDEX('Stato patrimoniale'!J:J,MATCH(A4,'Stato patrimoniale'!A:A,0)) -> USD | H4: =F4+D4*E4 -> 0.33 | I4: =INDEX('Stato patrimoniale'!N:N,MATCH(A4,'Stato patrimoniale'!A:A,0)) -> 0.26 | J4: =H4*I4 -> 0.0858 | K4: =H4-(H4*I4) -> 0.2442
A5: 23 | B5: 44545 | E5: 1 | F5: 29 | G5: =INDEX('Stato patrimoniale'!J:J,MATCH(A5,'Stato patrimoniale'!A:A,0)) -> USD | H5: =F5+D5*E5 -> 29 | I5: =INDEX('Stato patrimoniale'!N:N,MATCH(A5,'Stato patrimoniale'!A:A,0)) -> 0.26 | J5: =H5*I5 -> 7.54 | K5: =H5-(H5*I5) -> 21.46
A6: 21 | B6: 44607 | E6: 1 | F6: 0.33 | G6: =INDEX('Stato patrimoniale'!J:J,MATCH(A6,'Stato patrimoniale'!A:A,0)) -> USD | H6: =F6+D6*E6 -> 0.33 | I6: =INDEX('Stato patrimoniale'!N:N,MATCH(A6,'Stato patrimoniale'!A:A,0)) -> 0.26 | J6: =H6*I6 -> 0.0858 | K6: =H6-(H6*I6) -> 0.2442
A7: 23 | B7: 44637 | E7: 1 | F7: 37.2 | G7: =INDEX('Stato patrimoniale'!J:J,MATCH(A7,'Stato patrimoniale'!A:A,0)) -> USD | H7: =F7+D7*E7 -> 37.2 | I7: =INDEX('Stato patrimoniale'!N:N,MATCH(A7,'Stato patrimoniale'!A:A,0)) -> 0.26 | J7: =H7*I7 -> 9.672 | K7: =H7-(H7*I7) -> 27.528
A8: 21 | B8: 44697 | E8: 1 | F8: 0.37 | G8: =INDEX('Stato patrimoniale'!J:J,MATCH(A8,'Stato patrimoniale'!A:A,0)) -> USD | H8: =F8+D8*E8 -> 0.37 | I8: =INDEX('Stato patrimoniale'!N:N,MATCH(A8,'Stato patrimoniale'!A:A,0)) -> 0.26 | J8: =H8*I8 -> 0.0962 | K8: =H8-(H8*I8) -> 0.2738
A9: 23 | B9: 44726 | E9: 1 | F9: 39.33 | G9: =INDEX('Stato patrimoniale'!J:J,MATCH(A9,'Stato patrimoniale'!A:A,0)) -> USD | H9: =F9+D9*E9 -> 39.33 | I9: =INDEX('Stato patrimoniale'!N:N,MATCH(A9,'Stato patrimoniale'!A:A,0)) -> 0.26 | J9: =H9*I9 -> 10.2258 | K9: =H9-(H9*I9) -> 29.1042
A10: 21 | B10: 44789 | E10: 1 | F10: 0.38 | G10: =INDEX('Stato patrimoniale'!J:J,MATCH(A10,'Stato patrimoniale'!A:A,0)) -> USD | H10: =F10+D10*E10 -> 0.38 | I10: =INDEX('Stato patrimoniale'!N:N,MATCH(A10,'Stato patrimoniale'!A:A,0)) -> 0.26 | J10: =H10*I10 -> 0.0988 | K10: =H10-(H10*I10) -> 0.2812
A11: 23 | B11: 44817 | E11: 1 | F11: 40.4 | G11: =INDEX('Stato patrimoniale'!J:J,MATCH(A11,'Stato patrimoniale'!A:A,0)) -> USD | H11: =F11+D11*E11 -> 40.4 | I11: =INDEX('Stato patrimoniale'!N:N,MATCH(A11,'Stato patrimoniale'!A:A,0)) -> 0.26 | J11: =H11*I11 -> 10.504 | K11: =H11-(H11*I11) -> 29.896
A12: 21 | B12: 44825 | E12: 1 | F12: 0.37 | G12: =INDEX('Stato patrimoniale'!J:J,MATCH(A12,'Stato patrimoniale'!A:A,0)) -> USD | H12: =F12+D12*E12 -> 0.37 | I12: =INDEX('Stato patrimoniale'!N:N,MATCH(A12,'Stato patrimoniale'!A:A,0)) -> 0.26 | J12: =H12*I12 -> 0.0962 | K12: =H12-(H12*I12) -> 0.2738
A13: 21 | B13: 44879 | E13: 1 | F13: 0.38 | G13: =INDEX('Stato patrimoniale'!J:J,MATCH(A13,'Stato patrimoniale'!A:A,0)) -> USD | H13: =F13+D13*E13 -> 0.38 | I13: =INDEX('Stato patrimoniale'!N:N,MATCH(A13,'Stato patrimoniale'!A:A,0)) -> 0.26 | J13: =H13*I13 -> 0.0988 | K13: =H13-(H13*I13) -> 0.2812
A14: 23 | B14: 44910 | E14: 1 | F14: 42.44 | G14: =INDEX('Stato patrimoniale'!J:J,MATCH(A14,'Stato patrimoniale'!A:A,0)) -> USD | H14: =F14+D14*E14 -> 42.44 | I14: =INDEX('Stato patrimoniale'!N:N,MATCH(A14,'Stato patrimoniale'!A:A,0)) -> 0.26 | J14: =H14*I14 -> 11.0344 | K14: =H14-(H14*I14) -> 31.4056
A15: 21 | B15: 44977 | E15: 1 | F15: 0.37 | G15: =INDEX('Stato patrimoniale'!J:J,MATCH(A15,'Stato patrimoniale'!A:A,0)) -> USD | H15: =F15+D15*E15 -> 0.37 | I15: =INDEX('Stato patrimoniale'!N:N,MATCH(A15,'Stato patrimoniale'!A:A,0)) -> 0.26 | J15: =H15*I15 -> 0.0962 | K15: =H15-(H15*I15) -> 0.2738
... A17: 21 | B17: 45070 | E17: 1 | F17: 0.38 | G17: =INDEX('Stato patrimoniale'!J:J,MATCH(A17,'Stato patrimoniale'!A:A,0)) -> USD | H17: =F17+D17*E17 -> 0.38 | I17: =INDEX('Stato patrimoniale'!N:N,MATCH(A17,'Stato patrimoniale'!A:A,0)) -> 0.26 | J17: =H17*I17 -> 0.0988 | K17: =H17-(H17*I17) -> 0.2812
A18: 20 | B18: 45070 | D18: 0.88 | E18: 1 | G18: =INDEX('Stato patrimoniale'!J:J,MATCH(A18,'Stato patrimoniale'!A:A,0)) -> EUR | H18: =F18+D18*E18 -> 0.88 | I18: =INDEX('Stato patrimoniale'!N:N,MATCH(A18,'Stato patrimoniale'!A:A,0)) -> 0.26 | J18: =H18*I18 -> 0.2288 | K18: =H18-(H18*I18) -> 0.6512
A19: 23 | B19: 45089 | E19: 1 | F19: 42.42 | G19: =INDEX('Stato patrimoniale'!J:J,MATCH(A19,'Stato patrimoniale'!A:A,0)) -> USD | H19: =F19+D19*E19 -> 42.42 | I19: =INDEX('Stato patrimoniale'!N:N,MATCH(A19,'Stato patrimoniale'!A:A,0)) -> 0.26 | J19: =H19*I19 -> 11.0292 | K19: =H19-(H19*I19) -> 31.3908
A20: 19 | B20: 45133 | D20: 1.6 | E20: 1 | G20: =INDEX('Stato patrimoniale'!J:J,MATCH(A20,'Stato patrimoniale'!A:A,0)) -> EUR | H20: =F20+D20*E20 -> 1.6 | I20: =INDEX('Stato patrimoniale'!N:N,MATCH(A20,'Stato patrimoniale'!A:A,0)) -> 0.26 | J20: =H20*I20 -> 0.416 | K20: =H20-(H20*I20) -> 1.184
A21: 11 | B21: 45154 | D21: 149.99 | E21: 0.917 | G21: =INDEX('Stato patrimoniale'!J:J,MATCH(A21,'Stato patrimoniale'!A:A,0)) -> USD | H21: =F21+D21*E21 -> 137.54083 | I21: =INDEX('Stato patrimoniale'!N:N,MATCH(A21,'Stato patrimoniale'!A:A,0)) -> 0.125 | J21: =H21*I21 -> 17.192604 | K21: =H21-(H21*I21) -> 120.34823
A22: 23 | B22: 45188 | E22: 1 | F22: 37.4 | G22: =INDEX('Stato patrimoniale'!J:J,MATCH(A22,'Stato patrimoniale'!A:A,0)) -> USD | H22: =F22+D22*E22 -> 37.4 | I22: =INDEX('Stato patrimoniale'!N:N,MATCH(A22,'Stato patrimoniale'!A:A,0)) -> 0.26 | J22: =H22*I22 -> 9.724 | K22: =H22-(H22*I22) -> 27.676
A23: 20 | B23: 45189 | D23: 4.56 | E23: 1 | G23: =INDEX('Stato patrimoniale'!J:J,MATCH(A23,'Stato patrimoniale'!A:A,0)) -> EUR | H23: =F23+D23*E23 -> 4.56 | I23: =INDEX('Stato patrimoniale'!N:N,MATCH(A23,'Stato patrimoniale'!A:A,0)) -> 0.26 | J23: =H23*I23 -> 1.1856 | K23: =H23-(H23*I23) -> 3.3744
A24: 16 | B24: 45189 | D24: 0.24 | E24: 1 | G24: =INDEX('Stato patrimoniale'!J:J,MATCH(A24,'Stato patrimoniale'!A:A,0)) -> EUR | H24: =F24+D24*E24 -> 0.24 | I24: =INDEX('Stato patrimoniale'!N:N,MATCH(A24,'Stato patrimoniale'!A:A,0)) -> 0.26 | J24: =H24*I24 -> 0.0624 | K24: =H24-(H24*I24) -> 0.1776
A25: 6 | B25: 45196 | D25: 2.082 | E25: 1 | G25: =INDEX('Stato patrimoniale'!J:J,MATCH(A25,'Stato patrimoniale'!A:A,0)) -> EUR | H25: =F25+D25*E25 -> 2.082 | I25: =INDEX('Stato patrimoniale'!N:N,MATCH(A25,'Stato patrimoniale'!A:A,0)) -> 0.26 | J25: =H25*I25 -> 0.54132 | K25: =H25-(H25*I25) -> 1.54068
A26: 5 | B26: 45196 | D26: 1.388 | E26: 1 | G26: =INDEX('Stato patrimoniale'!J:J,MATCH(A26,'Stato patrimoniale'!A:A,0)) -> EUR | H26: =F26+D26*E26 -> 1.388 | I26: =INDEX('Stato patrimoniale'!N:N,MATCH(A26,'Stato patrimoniale'!A:A,0)) -> 0.26 | J26: =H26*I26 -> 0.36088 | K26: =H26-(H26*I26) -> 1.02712
A27: 3 | B27: 45196 | D27: 6.33 | E27: 1 | G27: =INDEX('Stato patrimoniale'!J:J,MATCH(A27,'Stato patrimoniale'!A:A,0)) -> EUR | H27: =F27+D27*E27 -> 6.33 | I27: =INDEX('Stato patrimoniale'!N:N,MATCH(A27,'Stato patrimoniale'!A:A,0)) -> 0.26 | J27: =H27*I27 -> 1.6458 | K27: =H27-(H27*I27) -> 4.6842
A28: 25 | B28: 45198 | D28: 31.3 | E28: 1 | G28: =INDEX('Stato patrimoniale'!J:J,MATCH(A28,'Stato patrimoniale'!A:A,0)) -> EUR | H28: =F28+D28*E28 -> 31.3 | I28: =INDEX('Stato patrimoniale'!N:N,MATCH(A28,'Stato patrimoniale'!A:A,0)) -> 0.125 | J28: =H28*I28 -> 3.9125 | K28: =H28-(H28*I28) -> 27.3875
A29: 12 | B29: 45201 | D29: 112.5 | E29: 1 | G29: =INDEX('Stato patrimoniale'!J:J,MATCH(A29,'Stato patrimoniale'!A:A,0)) -> EUR | H29: =F29+D29*E29 -> 112.5 | I29: =INDEX('Stato patrimoniale'!N:N,MATCH(A29,'Stato patrimoniale'!A:A,0)) -> 0.125 | J29: =H29*I29 -> 14.0625 | K29: =H29-(H29*I29) -> 98.4375
A30: 26 | B30: 45245 | E30: 1 | F30: 48.86 | G30: =INDEX('Stato patrimoniale'!J:J,MATCH(A30,'Stato patrimoniale'!A:A,0)) -> USD | H30: =F30+D30*E30 -> 48.86 | I30: =INDEX('Stato patrimoniale'!N:N,MATCH(A30,'Stato patrimoniale'!A:A,0)) -> 0.125 | J30: =H30*I30 -> 6.1075 | K30: =H30-(H30*I30) -> 42.7525
A31: 21 | B31: 45250 | E31: 1 | F31: 0.38 | G31: =INDEX('Stato patrimoniale'!J:J,MATCH(A31,'Stato patrimoniale'!A:A,0)) -> USD | H31: =F31+D31*E31 -> 0.38 | I31: =INDEX('Stato patrimoniale'!N:N,MATCH(A31,'Stato patrimoniale'!A:A,0)) -> 0.26 | J31: =H31*I31 -> 0.0988 | K31: =H31-(H31*I31) -> 0.2812
A32: 20 | B32: 45252 | D32: 4.37 | E32: 1 | G32: =INDEX('Stato patrimoniale'!J:J,MATCH(A32,'Stato patrimoniale'!A:A,0)) -> EUR | H32: =F32+D32*E32 -> 4.37 | I32: =INDEX('Stato patrimoniale'!N:N,MATCH(A32,'Stato patrimoniale'!A:A,0)) -> 0.26 | J32: =H32*I32 -> 1.1362 | K32: =H32-(H32*I32) -> 3.2338
A33: 17 | B33: 45252 | D33: 14.4 | E33: 1 | G33: =INDEX('Stato patrimoniale'!J:J,MATCH(A33,'Stato patrimoniale'!A:A,0)) -> EUR | H33: =F33+D33*E33 -> 14.4 | I33: =INDEX('Stato patrimoniale'!N:N,MATCH(A33,'Stato patrimoniale'!A:A,0)) -> 0.26 | J33: =H33*I33 -> 3.744 | K33: =H33-(H33*I33) -> 10.656
A34: 15 | B34: 45252 | D34: 5.93 | E34: 1 | G34: =INDEX('Stato patrimoniale'!J:J,MATCH(A34,'Stato patrimoniale'!A:A,0)) -> EUR | H34: =F34+D34*E34 -> 5.93 | I34: =INDEX('Stato patrimoniale'!N:N,MATCH(A34,'Stato patrimoniale'!A:A,0)) -> 0.26 | J34: =H34*I34 -> 1.5418 | K34: =H34-(H34*I34) -> 4.3882
A35: 4 | B35: 45259 | D35: 2.03 | E35: 1 | G35: =INDEX('Stato patrimoniale'!J:J,MATCH(A35,'Stato patrimoniale'!A:A,0)) -> EUR | H35: =F35+D35*E35 -> 2.03 | I35: =INDEX('Stato patrimoniale'!N:N,MATCH(A35,'Stato patrimoniale'!A:A,0)) -> 0.26 | J35: =H35*I35 -> 0.5278 | K35: =H35-(H35*I35) -> 1.5022
A36: 10 | B36: 45273 | D36: 162.5 | E36: 1 | G36: =INDEX('Stato patrimoniale'!J:J,MATCH(A36,'Stato patrimoniale'!A:A,0)) -> EUR | H36: =F36+D36*E36 -> 162.5 | I36: =INDEX('Stato patrimoniale'!N:N,MATCH(A36,'Stato patrimoniale'!A:A,0)) -> 0.125 | J36: =H36*I36 -> 20.3125 | K36: =H36-(H36*I36) -> 142.1875
A37: 16 | B37: 45273 | D37: 0.24 | E37: 1 | G37: =INDEX('Stato patrimoniale'!J:J,MATCH(A37,'Stato patrimoniale'!A:A,0)) -> EUR | H37: =F37+D37*E37 -> 0.24 | I37: =INDEX('Stato patrimoniale'!N:N,MATCH(A37,'Stato patrimoniale'!A:A,0)) -> 0.26 | J37: =H37*I37 -> 0.0624 | K37: =H37-(H37*I37) -> 0.1776
A38: 23 | B38: 45279 | E38: 1 | F38: 40.29 | G38: =INDEX('Stato patrimoniale'!J:J,MATCH(A38,'Stato patrimoniale'!A:A,0)) -> USD | H38: =F38+D38*E38 -> 40.29 | I38: =INDEX('Stato patrimoniale'!N:N,MATCH(A38,'Stato patrimoniale'!A:A,0)) -> 0.26 | J38: =H38*I38 -> 10.4754 | K38: =H38-(H38*I38) -> 29.8146
A39: 3 | B39: 45287 | D39: 1.6 | E39: 1 | G39: =INDEX('Stato patrimoniale'!J:J,MATCH(A39,'Stato patrimoniale'!A:A,0)) -> EUR | H39: =F39+D39*E39 -> 1.6 | I39: =INDEX('Stato patrimoniale'!N:N,MATCH(A39,'Stato patrimoniale'!A:A,0)) -> 0.26 | J39: =H39*I39 -> 0.416 | K39: =H39-(H39*I39) -> 1.184
A40: 5 | B40: 45289 | D40: 3.34 | E40: 1 | G40: =INDEX('Stato patrimoniale'!J:J,MATCH(A40,'Stato patrimoniale'!A:A,0)) -> EUR | H40: =F40+D40*E40 -> 3.34 | I40: =INDEX('Stato patrimoniale'!N:N,MATCH(A40,'Stato patrimoniale'!A:A,0)) -> 0.26 | J40: =H40*I40 -> 0.8684 | K40: =H40-(H40*I40) -> 2.4716
A41: 29 | B41: 45301 | D41: 51.25 | E41: 1 | G41: =INDEX('Stato patrimoniale'!J:J,MATCH(A41,'Stato patrimoniale'!A:A,0)) -> EUR | H41: =F41+D41*E41 -> 51.25 | I41: =INDEX('Stato patrimoniale'!N:N,MATCH(A41,'Stato patrimoniale'!A:A,0)) -> 0.125 | J41: =H41*I41 -> 6.40625 | K41: =H41-(H41*I41) -> 44.84375
...

Sheet Securities
A1: Ticker Symbol | B1: ISIN | C1: Security Name | D1: Currency
A2: =IF(INDEX('Stato patrimoniale'!L:L,MATCH(C2,'Stato patrimoniale'!C:C,0))<>0,INDEX('Stato patrimoniale'!L:L,MATCH(C2,'Stato patrimoniale'!C:C,0)),"") -> CNHI.VI | B2: =INDEX('Stato patrimoniale'!K:K,MATCH(C2,'Stato patrimoniale'!C:C,0)) -> NL0010545661 | C2: {=_xlfn.UNIQUE('Stato patrimoniale'!C2:C106)} -> CNH Industrial | D2: =INDEX('Stato patrimoniale'!J:J,MATCH(C2,'Stato patrimoniale'!C:C,0)) -> EUR
A3: =IF(INDEX('Stato patrimoniale'!L:L,MATCH(C3,'Stato patrimoniale'!C:C,0))<>0,INDEX('Stato patrimoniale'!L:L,MATCH(C3,'Stato patrimoniale'!C:C,0)),"") -> UCG.MI | B3: =INDEX('Stato patrimoniale'!K:K,MATCH(C3,'Stato patrimoniale'!C:C,0)) -> IT0005239360 | C3: Unicredit | D3: =INDEX('Stato patrimoniale'!J:J,MATCH(C3,'Stato patrimoniale'!C:C,0)) -> EUR
A4: =IF(INDEX('Stato patrimoniale'!L:L,MATCH(C4,'Stato patrimoniale'!C:C,0))<>0,INDEX('Stato patrimoniale'!L:L,MATCH(C4,'Stato patrimoniale'!C:C,0)),"") -> PST.MI | B4: =INDEX('Stato patrimoniale'!K:K,MATCH(C4,'Stato patrimoniale'!C:C,0)) -> IT0003796171 | C4: Poste Italiane | D4: =INDEX('Stato patrimoniale'!J:J,MATCH(C4,'Stato patrimoniale'!C:C,0)) -> EUR
A5: =IF(INDEX('Stato patrimoniale'!L:L,MATCH(C5,'Stato patrimoniale'!C:C,0))<>0,INDEX('Stato patrimoniale'!L:L,MATCH(C5,'Stato patrimoniale'!C:C,0)),"") -> STMMI.MI | B5: =INDEX('Stato patrimoniale'!K:K,MATCH(C5,'Stato patrimoniale'!C:C,0)) -> NL0000226223 | C5: STMicroElectronics | D5: =INDEX('Stato patrimoniale'!J:J,MATCH(C5,'Stato patrimoniale'!C:C,0)) -> EUR
A6: =IF(INDEX('Stato patrimoniale'!L:L,MATCH(C6,'Stato patrimoniale'!C:C,0))<>0,INDEX('Stato patrimoniale'!L:L,MATCH(C6,'Stato patrimoniale'!C:C,0)),"") -> ISP.MI | B6: =INDEX('Stato patrimoniale'!K:K,MATCH(C6,'Stato patrimoniale'!C:C,0)) -> IT0000072618 | C6: Intesa San Paolo | D6: =INDEX('Stato patrimoniale'!J:J,MATCH(C6,'Stato patrimoniale'!C:C,0)) -> EUR
A7: =IF(INDEX('Stato patrimoniale'!L:L,MATCH(C7,'Stato patrimoniale'!C:C,0))<>0,INDEX('Stato patrimoniale'!L:L,MATCH(C7,'Stato patrimoniale'!C:C,0)),"") -> LDO.MI | B7: =INDEX('Stato patrimoniale'!K:K,MATCH(C7,'Stato patrimoniale'!C:C,0)) -> IT0003856405 | C7: Leonardo | D7: =INDEX('Stato patrimoniale'!J:J,MATCH(C7,'Stato patrimoniale'!C:C,0)) -> EUR
A8: =IF(INDEX('Stato patrimoniale'!L:L,MATCH(C8,'Stato patrimoniale'!C:C,0))<>0,INDEX('Stato patrimoniale'!L:L,MATCH(C8,'Stato patrimoniale'!C:C,0)),"") -> ENEL.MI | B8: =INDEX('Stato patrimoniale'!K:K,MATCH(C8,'Stato patrimoniale'!C:C,0)) -> IT0003128367 | C8: Enel | D8: =INDEX('Stato patrimoniale'!J:J,MATCH(C8,'Stato patrimoniale'!C:C,0)) -> EUR
A9: =IF(INDEX('Stato patrimoniale'!L:L,MATCH(C9,'Stato patrimoniale'!C:C,0))<>0,INDEX('Stato patrimoniale'!L:L,MATCH(C9,'Stato patrimoniale'!C:C,0)),"") -> ENI.MI | B9: =INDEX('Stato patrimoniale'!K:K,MATCH(C9,'Stato patrimoniale'!C:C,0)) -> IT0003132476 | C9: Eni | D9: =INDEX('Stato patrimoniale'!J:J,MATCH(C9,'Stato patrimoniale'!C:C,0)) -> EUR
A10: =IF(INDEX('Stato patrimoniale'!L:L,MATCH(C10,'Stato patrimoniale'!C:C,0))<>0,INDEX('Stato patrimoniale'!L:L,MATCH(C10,'Stato patrimoniale'!C:C,0)),"") -> AAPL | B10: =INDEX('Stato patrimoniale'!K:K,MATCH(C10,'Stato patrimoniale'!C:C,0)) -> US0378331005 | C10: Apple | D10: =INDEX('Stato patrimoniale'!J:J,MATCH(C10,'Stato patrimoniale'!C:C,0)) -> USD
A11: =IF(INDEX('Stato patrimoniale'!L:L,MATCH(C11,'Stato patrimoniale'!C:C,0))<>0,INDEX('Stato patrimoniale'!L:L,MATCH(C11,'Stato patrimoniale'!C:C,0)),"") -> AMZN | B11: =INDEX('Stato patrimoniale'!K:K,MATCH(C11,'Stato patrimoniale'!C:C,0)) -> US0231351067 | C11: Amazon | D11: =INDEX('Stato patrimoniale'!J:J,MATCH(C11,'Stato patrimoniale'!C:C,0)) -> USD
A12: =IF(INDEX('Stato patrimoniale'!L:L,MATCH(C12,'Stato patrimoniale'!C:C,0))<>0,INDEX('Stato patrimoniale'!L:L,MATCH(C12,'Stato patrimoniale'!C:C,0)),"") -> MSFT | B12: =INDEX('Stato patrimoniale'!K:K,MATCH(C12,'Stato patrimoniale'!C:C,0)) -> US5949181045 | C12: Microsoft | D12: =INDEX('Stato patrimoniale'!J:J,MATCH(C12,'Stato patrimoniale'!C:C,0)) -> USD
A13: =IF(INDEX('Stato patrimoniale'!L:L,MATCH(C13,'Stato patrimoniale'!C:C,0))<>0,INDEX('Stato patrimoniale'!L:L,MATCH(C13,'Stato patrimoniale'!C:C,0)),"") -> SWDA.MI | B13: =INDEX('Stato patrimoniale'!K:K,MATCH(C13,'Stato patrimoniale'!C:C,0)) -> IE00B4L5Y983 | C13: iShares Core MSCI World UCITS ETF USD (Acc) | D13: =INDEX('Stato patrimoniale'!J:J,MATCH(C13,'Stato patrimoniale'!C:C,0)) -> EUR
A14: =IF(INDEX('Stato patrimoniale'!L:L,MATCH(C14,'Stato patrimoniale'!C:C,0))<>0,INDEX('Stato patrimoniale'!L:L,MATCH(C14,'Stato patrimoniale'!C:C,0)),"") -> VFEM.MI | B14: =INDEX('Stato patrimoniale'!K:K,MATCH(C14,'Stato patrimoniale'!C:C,0)) -> IE00B3VVMM84 | C14: Vanguard FTSE Emerging Markets UCITS ETF (USD) Dis | D14: =INDEX('Stato patrimoniale'!J:J,MATCH(C14,'Stato patrimoniale'!C:C,0)) -> EUR
... A45: =IF(INDEX('Stato patrimoniale'!L:L,MATCH(C45,'Stato patrimoniale'!C:C,0))<>0,INDEX('Stato patrimoniale'!L:L,MATCH(C45,'Stato patrimoniale'!C:C,0)),"") | B45: =INDEX('Stato patrimoniale'!K:K,MATCH(C45,'Stato patrimoniale'!C:C,0)) -> IT0005696320 | C45: BTP-10MZ32 VAL CUM | D45: =INDEX('Stato patrimoniale'!J:J,MATCH(C45,'Stato patrimoniale'!C:C,0)) -> EUR
C46: 0

Sheet Transactions_Buy
A1: Ticker Symbol | B1: ISIN | C1: Security Name | D1: Class | E1: Currency Gross Amount | F1: Shares | G1: Value | H1: Exchange rate | I1: fees | J1: taxes | K1: Date | L1: Type | M1: Securities account | N1: Cash Account
A2: ='Stato patrimoniale'!L2 -> CNHI.VI | B2: ='Stato patrimoniale'!K2 -> NL0010545661 | C2: ='Stato patrimoniale'!C2 -> CNH Industrial | D2: ='Stato patrimoniale'!D2 -> A | E2: ='Stato patrimoniale'!J2 -> EUR | F2: ='Stato patrimoniale'!I2 -> 18 | G2: ='Stato patrimoniale'!W2 -> 249.534 | H2: ='Stato patrimoniale'!U2 -> 1 | I2: ='Stato patrimoniale'!V2 -> 0 | K2: ='Stato patrimoniale'!O2 -> 45133 | L2: Buy | M2: ='Stato patrimoniale'!Q2 -> Fineco-C | N2: =M2 -> Fineco-C
A3: ='Stato patrimoniale'!L3 -> UCG.MI | B3: ='Stato patrimoniale'!K3 -> IT0005239360 | C3: ='Stato patrimoniale'!C3 -> Unicredit | D3: ='Stato patrimoniale'!D3 -> A | E3: ='Stato patrimoniale'!J3 -> EUR | F3: ='Stato patrimoniale'!I3 -> 11 | G3: ='Stato patrimoniale'!W3 -> 246.598 | H3: ='Stato patrimoniale'!U3 -> 1 | I3: ='Stato patrimoniale'!V3 -> 0 | K3: ='Stato patrimoniale'!O3 -> 45132 | L3: Buy | M3: ='Stato patrimoniale'!Q3 -> Fineco-C | N3: =M3 -> Fineco-C
